Workbook

Sheet 2025
A1: Rank | B1: Country | C1: Price To Income Ratio | D1: Gross Rental Yield City Centre | E1: Gross Rental Yield Outside of Centre | F1: Price To Rent Ratio City Centre | G1: Price To Rent Ratio Outside Of City Centre | H1: Mortgage As A Percentage Of Income | I1: Affordability Index
A2: 1 | B2: Syria | C2: 115.1 | D2: 2.4 | E2: 3.8 | F2: 41.1 | G2: 26.3 | H2: 1746.8 | I2: 0.1
A3: 2 | B3: Cuba | C3: 48 | D3: 24 | E3: 28.3 | F3: 4.2 | G3: 3.5 | H3: 530.3 | I3: 0.2
A4: 3 | B4: Ethiopia | C4: 47.1 | D4: 6 | E4: 5.4 | F4: 16.7 | G4: 18.6 | H4: 762.3 | I4: 0.1
A5: 4 | B5: Cameroon | C5: 46.6 | D5: 9.2 | E5: 11.4 | F5: 10.8 | G5: 8.8 | H5: 907.8 | I5: 0.1
A6: 5 | B6: Sri Lanka | C6: 34.2 | D6: 3.7 | E6: 2.7 | F6: 26.7 | G6: 36.5 | H6: 603.5 | I6: 0.2
A7: 6 | B7: Nepal | C7: 32.1 | D7: 1.7 | E7: 1.8 | F7: 60 | G7: 56.3 | H7: 447.4 | I7: 0.2
A8: 7 | B8: Hong Kong (China) | C8: 29.1 | D8: 1.9 | E8: 2.2 | F8: 52.2 | G8: 44.7 | H8: 211.2 | I8: 0.5
A9: 8 | B9: China | C9: 28.5 | D9: 1.6 | E9: 1.9 | F9: 62.5 | G9: 51.8 | H9: 212.9 | I9: 0.5
A10: 9 | B10: Vietnam | C10: 25.8 | D10: 3 | E10: 3.6 | F10: 33.3 | G10: 28 | H10: 296.2 | I10: 0.3
A11: 10 | B11: Thailand | C11: 25.2 | D11: 2.9 | E11: 3.2 | F11: 34 | G11: 31.5 | H11: 213.4 | I11: 0.5
A12: 11 | B12: Singapore | C12: 23.2 | D12: 2.9 | E12: 3.1 | F12: 34.2 | G12: 32.4 | H12: 158.4 | I12: 0.6
A13: 12 | B13: Philippines | C13: 22.2 | D13: 3 | E13: 3.5 | F13: 33.1 | G13: 28.5 | H13: 211.5 | I13: 0.5
... A105: 104 | B105: Saudi Arabia | C105: 3.1 | D105: 6.3 | E105: 7.4 | F105: 15.9 | G105: 13.5 | H105: 24 | I105: 4.2

Sheet 2015
A1: Rank | B1: Country | C1: Price To Income Ratio | D1: Gross Rental Yield City Centre | E1: Gross Rental Yield Outside of Centre | F1: Price To Rent Ratio City Centre | G1: Price To Rent Ratio Outside Of City Centre | H1: Mortgage As A Percentage Of Income | I1: Affordability Index
A2: 1 | B2: Uganda | C2: 31.1 | D2: 1.9 | E2: 10 | F2: 53.7 | G2: 10 | H2: 649.4 | I2: 0.2
A3: 2 | B3: Syria | C3: 30.5 | D3: 3.9 | E3: 3.1 | F3: 25.3 | G3: 31.8 | H3: 283.7 | I3: 0.4
A4: 3 | B4: Hong Kong | C4: 30.1 | D4: 2.7 | E4: 2.8 | F4: 37.5 | G4: 36.1 | H4: 193 | I4: 0.5
A5: 4 | B5: Myanmar | C5: 26.8 | D5: 8.5 | E5: 2.9 | F5: 11.8 | G5: 33.9 | H5: 318 | I5: 0.3
A6: 5 | B6: Ghana | C6: 26.6 | D6: 10.8 | E6: 13.4 | F6: 9.3 | G6: 7.4 | H6: 670.4 | I6: 0.1
A7: 6 | B7: China | C7: 26.4 | D7: 2.8 | E7: 3 | F7: 35.9 | G7: 33.3 | H7: 230.6 | I7: 0.4
A8: 7 | B8: El Salvador | C8: 25.4 | D8: 5.3 | E8: 1.7 | F8: 18.9 | G8: 60.3 | H8: 336.1 | I8: 0.3
A9: 8 | B9: Taiwan | C9: 25 | D9: 1.4 | E9: 1.8 | F9: 71.4 | G9: 55.5 | H9: 152.3 | I9: 0.7
A10: 9 | B10: Vietnam | C10: 23.9 | D10: 5.2 | E10: 7.6 | F10: 19.3 | G10: 13.1 | H10: 285.6 | I10: 0.4
A11: 10 | B11: Venezuela | C11: 22.2 | D11: 12.5 | E11: 9.3 | F11: 8 | G11: 10.8 | H11: 333.4 | I11: 0.3
A12: 11 | B12: Mauritius | C12: 22.1 | D12: 2.2 | E12: 2.4 | F12: 45.3 | G12: 41.5 | H12: 228.8 | I12: 0.4
A13: 12 | B13: Singapore | C13: 21.4 | D13: 3.4 | E13: 3.9 | F13: 29.2 | G13: 25.7 | H13: 133.3 | I13: 0.8
... A122: 121 | B122: Tanzania | C122: 1.8 | D122: 80.3 | E122: 27.8 | F122: 1.2 | G122: 3.6 | H122: 27.9 | I122: 3.6

Sheet Sheet3
B1: 2025 | C1: 2025 | D1: 2015 | E1: 2015
A2: Country | B2: GDP per capita | C2: Mortgage as a percentage of Income | D2: GDP per capita | E2: Mortgage as a percentage of Income | J2: Country Name | K2: Country Code | L2: 2024 | N2: Country Name | O2: Country Code | P2: 2015
A3: Albania | B3: =VLOOKUP(A3,$J$3:$L$268,3,FALSE) -> 27146.381 | C3: =VLOOKUP(A3,'2025'!$B$2:$H$105,2,FALSE)/100 -> 0.153 | D3: =VLOOKUP(A3,$N$3:$P$268,3,FALSE) -> 11571.707 | E3: =VLOOKUP(A3,'2015'!$B$2:$H$122,2,FALSE)/100 -> 0.146 | F3: =B3/D3-1 -> 1.3459272 | J3: Aruba | K3: ABW | L3: 50649.302 | N3: Aruba | O3: ABW | P3: 35972.86 | R3: Czech Republic | S3: Czechia
A4: Algeria | B4: =VLOOKUP(A4,$J$3:$L$268,3,FALSE) -> 17620.742 | C4: =VLOOKUP(A4,'2025'!$B$2:$H$105,2,FALSE)/100 -> 0.167 | D4: =VLOOKUP(A4,$N$3:$P$268,3,FALSE) -> 13807.352 | E4: =VLOOKUP(A4,'2015'!$B$2:$H$122,2,FALSE)/100 -> 0.209 | J4: Africa Eastern and Southern | K4: AFE | L4: 4635.7882 | N4: Africa Eastern and Southern | O4: AFE | P4: 3539.8155 | R4: Egypt | S4: Egypt, Arab Rep.
A5: Argentina | B5: =VLOOKUP(A5,$J$3:$L$268,3,FALSE) -> 30431.193 | C5: =VLOOKUP(A5,'2025'!$B$2:$H$105,2,FALSE)/100 -> 0.177 | D5: =VLOOKUP(A5,$N$3:$P$268,3,FALSE) -> 19899.15 | E5: =VLOOKUP(A5,'2015'!$B$2:$H$122,2,FALSE)/100 -> 0.116 | J5: Afghanistan | K5: AFG | N5: Afghanistan | O5: AFG | P5: 2284.0758 | R5: Hong Kong (China) | S5: Hong Kong SAR, China
A6: Armenia | B6: =VLOOKUP(A6,$J$3:$L$268,3,FALSE) -> 22823.18 | C6: =VLOOKUP(A6,'2025'!$B$2:$H$105,2,FALSE)/100 -> 0.194 | D6: =VLOOKUP(A6,$N$3:$P$268,3,FALSE) -> 9756.8408 | E6: =VLOOKUP(A6,'2015'!$B$2:$H$122,2,FALSE)/100 -> 0.134 | J6: Africa Western and Central | K6: AFW | L6: 6815.991 | N6: Africa Western and Central | O6: AFW | P6: 5056.7394 | R6: Iran | S6: Iran, Islamic Rep.
A7: Australia | B7: =VLOOKUP(A7,$J$3:$L$268,3,FALSE) -> 72111.184 | C7: =VLOOKUP(A7,'2025'!$B$2:$H$105,2,FALSE)/100 -> 0.081 | D7: =VLOOKUP(A7,$N$3:$P$268,3,FALSE) -> 46464.587 | E7: =VLOOKUP(A7,'2015'!$B$2:$H$122,2,FALSE)/100 -> 0.071 | J7: Angola | K7: AGO | L7: 10118.609 | N7: Angola | O7: AGO | P7: 8067.4858 | R7: Kosovo (Disputed Territory)
A8: Austria | B8: =VLOOKUP(A8,$J$3:$L$268,3,FALSE) -> 73911.44 | C8: =VLOOKUP(A8,'2025'!$B$2:$H$105,2,FALSE)/100 -> 0.115 | D8: =VLOOKUP(A8,$N$3:$P$268,3,FALSE) -> 49549.316 | E8: =VLOOKUP(A8,'2015'!$B$2:$H$122,2,FALSE)/100 -> 0.096 | J8: Albania | K8: ALB | L8: 27146.381 | N8: Albania | O8: ALB | P8: 11571.707 | R8: Kyrgyzstan | S8: Kyrgyz Republic
A9: Azerbaijan | B9: =VLOOKUP(A9,$J$3:$L$268,3,FALSE) -> 25088.999 | C9: =VLOOKUP(A9,'2025'!$B$2:$H$105,2,FALSE)/100 -> 0.156 | D9: =VLOOKUP(A9,$N$3:$P$268,3,FALSE) -> 15075.273 | E9: =VLOOKUP(A9,'2015'!$B$2:$H$122,2,FALSE)/100 -> 0.162 | J9: Andorra | K9: AND | L9: 74939.475 | N9: Andorra | O9: AND | P9: 50733.239 | R9: Palestine
A10: Bangladesh | B10: =VLOOKUP(A10,$J$3:$L$268,3,FALSE) -> 9646.7698 | C10: =VLOOKUP(A10,'2025'!$B$2:$H$105,2,FALSE)/100 -> 0.128 | D10: =VLOOKUP(A10,$N$3:$P$268,3,FALSE) -> 4212.2358 | E10: =VLOOKUP(A10,'2015'!$B$2:$H$122,2,FALSE)/100 -> 0.109 | J10: Arab World | K10: ARB | L10: 18870.315 | N10: Arab World | O10: ARB | P10: 14332.866 | R10: Puerto Rico
A11: Belarus | B11: =VLOOKUP(A11,$J$3:$L$268,3,FALSE) -> 33010.331 | C11: =VLOOKUP(A11,'2025'!$B$2:$H$105,2,FALSE)/100 -> 0.128 | D11: =VLOOKUP(A11,$N$3:$P$268,3,FALSE) -> 18133.531 | E11: =VLOOKUP(A11,'2015'!$B$2:$H$122,2,FALSE)/100 -> 0.164 | J11: United Arab Emirates | K11: ARE | L11: 79228.739 | N11: United Arab Emirates | O11: ARE | P11: 73986.064 | R11: Russia | S11: Russian Federation
A12: Belgium | B12: =VLOOKUP(A12,$J$3:$L$268,3,FALSE) -> 73514.483 | C12: =VLOOKUP(A12,'2025'!$B$2:$H$105,2,FALSE)/100 -> 0.068 | D12: =VLOOKUP(A12,$N$3:$P$268,3,FALSE) -> 46071.915 | E12: =VLOOKUP(A12,'2015'!$B$2:$H$122,2,FALSE)/100 -> 0.065 | J12: Argentina | K12: ARG | L12: 30431.193 | N12: Argentina | O12: ARG | P12: 19899.15 | R12: Slovakia | S12: Slovak Republic
A13: Bolivia | B13: =VLOOKUP(A13,$J$3:$L$268,3,FALSE) -> 12877.635 | C13: =VLOOKUP(A13,'2025'!$B$2:$H$105,2,FALSE)/100 -> 0.12 | D13: =VLOOKUP(A13,$N$3:$P$268,3,FALSE) -> 8757.3178 | E13: =VLOOKUP(A13,'2015'!$B$2:$H$122,2,FALSE)/100 -> 0.103 | J13: Armenia | K13: ARM | L13: 22823.18 | N13: Armenia | O13: ARM | P13: 9756.8408 | R13: South Korea | S13: Korea, Rep.
A14: Bosnia And Herzegovina | B14: =VLOOKUP(A14,$J$3:$L$268,3,FALSE) -> 23345.497 | C14: =VLOOKUP(A14,'2025'!$B$2:$H$105,2,FALSE)/100 -> 0.132 | D14: =VLOOKUP(A14,$N$3:$P$268,3,FALSE) -> 11066.154 | E14: =VLOOKUP(A14,'2015'!$B$2:$H$122,2,FALSE)/100 -> 0.125 | J14: American Samoa | K14: ASM | N14: American Samoa | O14: ASM | R14: Taiwan
A15: Brazil | B15: =VLOOKUP(A15,$J$3:$L$268,3,FALSE) -> 22338.477 | C15: =VLOOKUP(A15,'2025'!$B$2:$H$105,2,FALSE)/100 -> 0.152 | D15: =VLOOKUP(A15,$N$3:$P$268,3,FALSE) -> 14821.438 | E15: =VLOOKUP(A15,'2015'!$B$2:$H$122,2,FALSE)/100 -> 0.167 | J15: Antigua and Barbuda | K15: ATG | L15: 33386.192 | N15: Antigua and Barbuda | O15: ATG | P15: 20985.439 | R15: Turkey | S15: Turkiye
A16: Bulgaria | B16: =VLOOKUP(A16,$J$3:$L$268,3,FALSE) -> 42224.445 | C16: =VLOOKUP(A16,'2025'!$B$2:$H$105,2,FALSE)/100 -> 0.093 | D16: =VLOOKUP(A16,$N$3:$P$268,3,FALSE) -> 17652.947 | E16: =VLOOKUP(A16,'2015'!$B$2:$H$122,2,FALSE)/100 -> 0.094 | J16: Australia | K16: AUS | L16: 72111.184 | N16: Australia | O16: AUS | P16: 46464.587 | R16: Venezuela | S16: Venezuela, RB
A17: Cameroon | B17: =VLOOKUP(A17,$J$3:$L$268,3,FALSE) -> 5588.9865 | C17: =VLOOKUP(A17,'2025'!$B$2:$H$105,2,FALSE)/100 -> 0.466 | D17: =VLOOKUP(A17,$N$3:$P$268,3,FALSE) -> 3497.6607 | E17: =VLOOKUP(A17,'2015'!$B$2:$H$122,2,FALSE)/100 -> #N/A | J17: Austria | K17: AUT | L17: 73911.44 | N17: Austria | O17: AUT | P17: 49549.316 | R17: Vietnam | S17: Viet Nam
A18: Canada | B18: =VLOOKUP(A18,$J$3:$L$268,3,FALSE) -> 64610.38 | C18: =VLOOKUP(A18,'2025'!$B$2:$H$105,2,FALSE)/100 -> 0.102 | D18: =VLOOKUP(A18,$N$3:$P$268,3,FALSE) -> 44668.091 | E18: =VLOOKUP(A18,'2015'!$B$2:$H$122,2,FALSE)/100 -> 0.055 | J18: Azerbaijan | K18: AZE | L18: 25088.999 | N18: Azerbaijan | O18: AZE | P18: 15075.273
A19: Chile | B19: =VLOOKUP(A19,$J$3:$L$268,3,FALSE) -> 36181.157 | C19: =VLOOKUP(A19,'2025'!$B$2:$H$105,2,FALSE)/100 -> 0.156 | D19: =VLOOKUP(A19,$N$3:$P$268,3,FALSE) -> 22468.313 | E19: =VLOOKUP(A19,'2015'!$B$2:$H$122,2,FALSE)/100 -> 0.108 | J19: Burundi | K19: BDI | L19: 1194.9468 | N19: Burundi | O19: BDI | P19: 722.0329
A20: China | B20: =VLOOKUP(A20,$J$3:$L$268,3,FALSE) -> 27104.87 | C20: =VLOOKUP(A20,'2025'!$B$2:$H$105,2,FALSE)/100 -> 0.285 | D20: =VLOOKUP(A20,$N$3:$P$268,3,FALSE) -> 13463.333 | E20: =VLOOKUP(A20,'2015'!$B$2:$H$122,2,FALSE)/100 -> 0.264 | J20: Belgium | K20: BEL | L20: 73514.483 | N20: Belgium | O20: BEL | P20: 46071.915
A21: Colombia | B21: =VLOOKUP(A21,$J$3:$L$268,3,FALSE) -> 22349.436 | C21: =VLOOKUP(A21,'2025'!$B$2:$H$105,2,FALSE)/100 -> 0.181 | D21: =VLOOKUP(A21,$N$3:$P$268,3,FALSE) -> 13332.056 | E21: =VLOOKUP(A21,'2015'!$B$2:$H$122,2,FALSE)/100 -> 0.144 | J21: Benin | K21: BEN | L21: 4434.5642 | N21: Benin | O21: BEN | P21: 2725.3372
A22: Costa Rica | B22: =VLOOKUP(A22,$J$3:$L$268,3,FALSE) -> 31106.764 | C22: =VLOOKUP(A22,'2025'!$B$2:$H$105,2,FALSE)/100 -> 0.103 | D22: =VLOOKUP(A22,$N$3:$P$268,3,FALSE) -> 17525.14 | E22: =VLOOKUP(A22,'2015'!$B$2:$H$122,2,FALSE)/100 -> 0.057 | J22: Burkina Faso | K22: BFA | L22: 2895.8915 | N22: Burkina Faso | O22: BFA | P22: 1691.5794
A23: Croatia | B23: =VLOOKUP(A23,$J$3:$L$268,3,FALSE) -> 49645.746 | C23: =VLOOKUP(A23,'2025'!$B$2:$H$105,2,FALSE)/100 -> 0.128 | D23: =VLOOKUP(A23,$N$3:$P$268,3,FALSE) -> 22187.177 | E23: =VLOOKUP(A23,'2015'!$B$2:$H$122,2,FALSE)/100 -> 0.125 | J23: Bangladesh | K23: BGD | L23: 9646.7698 | N23: Bangladesh | O23: BGD | P23: 4212.2358
A24: Cyprus | B24: =VLOOKUP(A24,$J$3:$L$268,3,FALSE) -> 62312.074 | C24: =VLOOKUP(A24,'2025'!$B$2:$H$105,2,FALSE)/100 -> 0.082 | D24: =VLOOKUP(A24,$N$3:$P$268,3,FALSE) -> 29315.725 | E24: =VLOOKUP(A24,'2015'!$B$2:$H$122,2,FALSE)/100 -> 0.074 | J24: Bulgaria | K24: BGR | L24: 42224.445 | N24: Bulgaria | O24: BGR | P24: 17652.947
A25: Czechia | B25: =VLOOKUP(A25,$J$3:$L$268,3,FALSE) -> 57285.424 | C25: =VLOOKUP(A25,'2025'!$B$2:$H$105,2,FALSE)/100 -> #N/A | D25: =VLOOKUP(A25,$N$3:$P$268,3,FALSE) -> 34093.028 | E25: =VLOOKUP(A25,'2015'!$B$2:$H$122,2,FALSE)/100 -> #N/A | J25: Bahrain | K25: BHR | L25: 66941.243 | N25: Bahrain | O25: BHR | P25: 48034.247
A26: Denmark | B26: =VLOOKUP(A26,$J$3:$L$268,3,FALSE) -> 81878.235 | C26: =VLOOKUP(A26,'2025'!$B$2:$H$105,2,FALSE)/100 -> 0.065 | D26: =VLOOKUP(A26,$N$3:$P$268,3,FALSE) -> 48897.21 | E26: =VLOOKUP(A26,'2015'!$B$2:$H$122,2,FALSE)/100 -> 0.05 | J26: Bahamas, The | K26: BHS | L26: 41197.934 | N26: Bahamas, The | O26: BHS | P26: 32137.578
A27: Dominican Republic | B27: =VLOOKUP(A27,$J$3:$L$268,3,FALSE) -> 27541.663 | C27: =VLOOKUP(A27,'2025'!$B$2:$H$105,2,FALSE)/100 -> 0.165 | D27: =VLOOKUP(A27,$N$3:$P$268,3,FALSE) -> 14804.097 | E27: =VLOOKUP(A27,'2015'!$B$2:$H$122,2,FALSE)/100 -> 0.115 | J27: Bosnia and Herzegovina | K27: BIH | L27: 23345.497 | N27: Bosnia and Herzegovina | O27: BIH | P27: 11066.154
A28: Ecuador | B28: =VLOOKUP(A28,$J$3:$L$268,3,FALSE) -> 15840.267 | C28: =VLOOKUP(A28,'2025'!$B$2:$H$105,2,FALSE)/100 -> 0.119 | D28: =VLOOKUP(A28,$N$3:$P$268,3,FALSE) -> 10877.751 | E28: =VLOOKUP(A28,'2015'!$B$2:$H$122,2,FALSE)/100 -> 0.147 | J28: Belarus | K28: BLR | L28: 33010.331 | N28: Belarus | O28: BLR | P28: 18133.531
A29: Egypt, Arab Rep. | B29: =VLOOKUP(A29,$J$3:$L$268,3,FALSE) -> 19094.145 | C29: =VLOOKUP(A29,'2025'!$B$2:$H$105,2,FALSE)/100 -> #N/A | D29: =VLOOKUP(A29,$N$3:$P$268,3,FALSE) -> 10903.337 | E29: =VLOOKUP(A29,'2015'!$B$2:$H$122,2,FALSE)/100 -> #N/A | J29: Belize | K29: BLZ | L29: 14346.519 | N29: Belize | O29: BLZ | P29: 9538.3869
... A34: France | B34: =VLOOKUP(A34,$J$3:$L$268,3,FALSE) -> 62556.918 | C34: =VLOOKUP(A34,'2025'!$B$2:$H$105,2,FALSE)/100 -> 0.103 | D34: =VLOOKUP(A34,$N$3:$P$268,3,FALSE) -> 40905.177 | E34: =VLOOKUP(A34,'2015'!$B$2:$H$122,2,FALSE)/100 -> 0.097 | J34: Brunei Darussalam | K34: BRN | L34: 89879.361 | N34: Brunei Darussalam | O34: BRN | P34: 62707.826
A35: Georgia | B35: =VLOOKUP(A35,$J$3:$L$268,3,FALSE) -> 28285.073 | C35: =VLOOKUP(A35,'2025'!$B$2:$H$105,2,FALSE)/100 -> 0.127 | D35: =VLOOKUP(A35,$N$3:$P$268,3,FALSE) -> 12269.653 | E35: =VLOOKUP(A35,'2015'!$B$2:$H$122,2,FALSE)/100 -> 0.152 | J35: Bhutan | K35: BTN | N35: Bhutan | O35: BTN | P35: 10213.814
A36: Germany | B36: =VLOOKUP(A36,$J$3:$L$268,3,FALSE) -> 73551.935 | C36: =VLOOKUP(A36,'2025'!$B$2:$H$105,2,FALSE)/100 -> 0.089 | D36: =VLOOKUP(A36,$N$3:$P$268,3,FALSE) -> 48545.401 | E36: =VLOOKUP(A36,'2015'!$B$2:$H$122,2,FALSE)/100 -> 0.066 | J36: Botswana | K36: BWA | L36: 20538.132 | N36: Botswana | O36: BWA | P36: 14143.694
A37: Greece | B37: =VLOOKUP(A37,$J$3:$L$268,3,FALSE) -> 44327.21 | C37: =VLOOKUP(A37,'2025'!$B$2:$H$105,2,FALSE)/100 -> 0.13 | D37: =VLOOKUP(A37,$N$3:$P$268,3,FALSE) -> 26607.726 | E37: =VLOOKUP(A37,'2015'!$B$2:$H$122,2,FALSE)/100 -> 0.097 | J37: Central African Republic | K37: CAF | L37: 1263.1023 | N37: Central African Republic | O37: CAF | P37: 768.87089
A38: Hong Kong SAR, China | B38: =VLOOKUP(A38,$J$3:$L$268,3,FALSE) -> 75195.987 | C38: =VLOOKUP(A38,'2025'!$B$2:$H$105,2,FALSE)/100 -> #N/A | D38: =VLOOKUP(A38,$N$3:$P$268,3,FALSE) -> 56043.043 | E38: =VLOOKUP(A38,'2015'!$B$2:$H$122,2,FALSE)/100 -> #N/A | J38: Canada | K38: CAN | L38: 64610.38 | N38: Canada | O38: CAN | P38: 44668.091
A39: Hungary | B39: =VLOOKUP(A39,$J$3:$L$268,3,FALSE) -> 48552.471 | C39: =VLOOKUP(A39,'2025'!$B$2:$H$105,2,FALSE)/100 -> 0.13 | D39: =VLOOKUP(A39,$N$3:$P$268,3,FALSE) -> 26937.732 | E39: =VLOOKUP(A39,'2015'!$B$2:$H$122,2,FALSE)/100 -> 0.086 | J39: Central Europe and the Baltics | K39: CEB | L39: 50599.212 | N39: Central Europe and the Baltics | O39: CEB | P39: 25780.239
A40: Iceland | B40: =VLOOKUP(A40,$J$3:$L$268,3,FALSE) -> 84256.845 | C40: =VLOOKUP(A40,'2025'!$B$2:$H$105,2,FALSE)/100 -> 0.067 | D40: =VLOOKUP(A40,$N$3:$P$268,3,FALSE) -> 49201.064 | E40: =VLOOKUP(A40,'2015'!$B$2:$H$122,2,FALSE)/100 -> 0.056 | J40: Switzerland | K40: CHE | L40: 96497.695 | N40: Switzerland | O40: CHE | P40: 65265.046
A41: India | B41: =VLOOKUP(A41,$J$3:$L$268,3,FALSE) -> 11159.986 | C41: =VLOOKUP(A41,'2025'!$B$2:$H$105,2,FALSE)/100 -> 0.109 | D41: =VLOOKUP(A41,$N$3:$P$268,3,FALSE) -> 5425.036 | E41: =VLOOKUP(A41,'2015'!$B$2:$H$122,2,FALSE)/100 -> 0.101 | J41: Channel Islands | K41: CHI | N41: Channel Islands | O41: CHI
A42: Indonesia | B42: =VLOOKUP(A42,$J$3:$L$268,3,FALSE) -> 16448.276 | C42: =VLOOKUP(A42,'2025'!$B$2:$H$105,2,FALSE)/100 -> 0.149 | D42: =VLOOKUP(A42,$N$3:$P$268,3,FALSE) -> 10027.537 | E42: =VLOOKUP(A42,'2015'!$B$2:$H$122,2,FALSE)/100 -> 0.189 | J42: Chile | K42: CHL | L42: 36181.157 | N42: Chile | O42: CHL | P42: 22468.313
A43: Iran, Islamic Rep. | B43: =VLOOKUP(A43,$J$3:$L$268,3,FALSE) -> 19873.886 | C43: =VLOOKUP(A43,'2025'!$B$2:$H$105,2,FALSE)/100 -> #N/A | D43: =VLOOKUP(A43,$N$3:$P$268,3,FALSE) -> 14273.55 | E43: =VLOOKUP(A43,'2015'!$B$2:$H$122,2,FALSE)/100 -> #N/A | J43: China | K43: CHN | L43: 27104.87 | N43: China | O43: CHN | P43: 13463.333
A44: Iraq | B44: =VLOOKUP(A44,$J$3:$L$268,3,FALSE) -> 14464.319 | C44: =VLOOKUP(A44,'2025'!$B$2:$H$105,2,FALSE)/100 -> 0.084 | D44: =VLOOKUP(A44,$N$3:$P$268,3,FALSE) -> 9334.466 | E44: =VLOOKUP(A44,'2015'!$B$2:$H$122,2,FALSE)/100 -> 0.089 | J44: Cote d'Ivoire | K44: CIV | L44: 7669.232 | N44: Cote d'Ivoire | O44: CIV | P44: 4403.643
...

Sheet Sheet4
C1: 2025 | D1: 2025 | E1: 2025 | F1: 2015 | G1: 2015 | H1: 2015
A2: Income group | B2: Country | C2: GDP per capita | D2: Price to Income | E2: REP price | F2: GDP per capita | G2: Price to Income | H2: REP price | I2: GDP growth | J2: REP growth
A3: =VLOOKUP(B3,'List of economies'!$A$2:$D$219,4,FALSE) -> High income | B3: Australia | C3: 72111.184 | D3: 0.081 | E3: =C3*D3 -> 5841.0059 | F3: 46464.587 | G3: 0.071 | H3: =F3*G3 -> 3298.9857 | I3: =C3/F3-1 -> 0.55196009 | J3: =E3/H3-1 -> 0.77054602 | K3: =J3/I3 -> 1.3960176
A4: =VLOOKUP(B4,'List of economies'!$A$2:$D$219,4,FALSE) -> High income | B4: Austria | C4: 73911.44 | D4: 0.115 | E4: =C4*D4 -> 8499.8156 | F4: 49549.316 | G4: 0.096 | H4: =F4*G4 -> 4756.7344 | I4: =C4/F4-1 -> 0.49167426 | J4: =E4/H4-1 -> 0.78690146 | K4: =J4/I4 -> 1.6004528
A5: =VLOOKUP(B5,'List of economies'!$A$2:$D$219,4,FALSE) -> High income | B5: Belgium | C5: 73514.483 | D5: 0.068 | E5: =C5*D5 -> 4998.9849 | F5: 46071.915 | G5: 0.065 | H5: =F5*G5 -> 2994.6745 | I5: =C5/F5-1 -> 0.59564636 | J5: =E5/H5-1 -> 0.66929157 | K5: =J5/I5 -> 1.1236392
A6: =VLOOKUP(B6,'List of economies'!$A$2:$D$219,4,FALSE) -> High income | B6: Bulgaria | C6: 42224.445 | D6: 0.093 | E6: =C6*D6 -> 3926.8733 | F6: 17652.947 | G6: 0.094 | H6: =F6*G6 -> 1659.377 | I6: =C6/F6-1 -> 1.3919204 | J6: =E6/H6-1 -> 1.3664745 | K6: =J6/I6 -> 0.98171881
A7: =VLOOKUP(B7,'List of economies'!$A$2:$D$219,4,FALSE) -> High income | B7: Canada | C7: 64610.38 | D7: 0.102 | E7: =C7*D7 -> 6590.2587 | F7: 44668.091 | G7: 0.055 | H7: =F7*G7 -> 2456.745 | I7: =C7/F7-1 -> 0.4464549 | J7: =E7/H7-1 -> 1.6825164 | K7: =J7/I7 -> 3.7686144
A8: =VLOOKUP(B8,'List of economies'!$A$2:$D$219,4,FALSE) -> High income | B8: Chile | C8: 36181.157 | D8: 0.156 | E8: =C8*D8 -> 5644.2604 | F8: 22468.313 | G8: 0.108 | H8: =F8*G8 -> 2426.5778 | I8: =C8/F8-1 -> 0.61031927 | J8: =E8/H8-1 -> 1.3260167 | K8: =J8/I8 -> 2.1726608
A9: =VLOOKUP(B9,'List of economies'!$A$2:$D$219,4,FALSE) -> High income | B9: Costa Rica | C9: 31106.764 | D9: 0.103 | E9: =C9*D9 -> 3203.9967 | F9: 17525.14 | G9: 0.057 | H9: =F9*G9 -> 998.93301 | I9: =C9/F9-1 -> 0.77497946 | J9: =E9/H9-1 -> 2.207419 | K9: =J9/I9 -> 2.8483581
A10: =VLOOKUP(B10,'List of economies'!$A$2:$D$219,4,FALSE) -> High income | B10: Croatia | C10: 49645.746 | D10: 0.128 | E10: =C10*D10 -> 6354.6554 | F10: 22187.177 | G10: 0.125 | H10: =F10*G10 -> 2773.3972 | I10: =C10/F10-1 -> 1.2375873 | J10: =E10/H10-1 -> 1.2912894 | K10: =J10/I10 -> 1.0433926
A11: =VLOOKUP(B11,'List of economies'!$A$2:$D$219,4,FALSE) -> High income | B11: Cyprus | C11: 62312.074 | D11: 0.082 | E11: =C11*D11 -> 5109.5901 | F11: 29315.725 | G11: 0.074 | H11: =F11*G11 -> 2169.3636 | I11: =C11/F11-1 -> 1.1255512 | J11: =E11/H11-1 -> 1.3553405 | K11: =J11/I11 -> 1.2041571
A12: =VLOOKUP(B12,'List of economies'!$A$2:$D$219,4,FALSE) -> High income | B12: Denmark | C12: 81878.235 | D12: 0.065 | E12: =C12*D12 -> 5322.0853 | F12: 48897.21 | G12: 0.05 | H12: =F12*G12 -> 2444.8605 | I12: =C12/F12-1 -> 0.67449707 | J12: =E12/H12-1 -> 1.1768462 | K12: =J12/I12 -> 1.7447758
A13: =VLOOKUP(B13,'List of economies'!$A$2:$D$219,4,FALSE) -> High income | B13: Estonia | C13: 49968.711 | D13: 0.114 | E13: =C13*D13 -> 5696.433 | F13: 29712.63 | G13: 0.116 | H13: =F13*G13 -> 3446.6651 | I13: =C13/F13-1 -> 0.68173302 | J13: =E13/H13-1 -> 0.65273762 | K13: =J13/I13 -> 0.95746811
A14: =VLOOKUP(B14,'List of economies'!$A$2:$D$219,4,FALSE) -> High income | B14: Finland | C14: 65378.384 | D14: 0.08 | E14: =C14*D14 -> 5230.2707 | F14: 42257.859 | G14: 0.07 | H14: =F14*G14 -> 2958.0502 | I14: =C14/F14-1 -> 0.54712958 | J14: =E14/H14-1 -> 0.76814809 | K14: =J14/I14 -> 1.4039601
... A86: =VLOOKUP(B86,'List of economies'!$A$2:$D$219,4,FALSE) -> Upper middle income | B86: Ukraine | C86: 18550.463 | D86: 0.136 | E86: =C86*D86 -> 2522.863 | F86: 9921.834 | G86: 0.174 | H86: =F86*G86 -> 1726.3991 | I86: =C86/F86-1 -> 0.86966068 | J86: =E86/H86-1 -> 0.46134398 | K86: =J86/I86 -> 0.53048734
B87: Turkiye | C87: 45639.019 | D87: 0.107 | E87: =C87*D87 -> 4883.3751 | F87: 25890.055 | G87: 0.067 | H87: =F87*G87 -> 1734.6337 | I87: =C87/F87-1 -> 0.76280118 | J87: =E87/H87-1 -> 1.8152198 | K87: =J87/I87 -> 2.3796762

Sheet Sheet5
A1: Ok or not? | B1: Income group | C1: Country | D1: REP growth per income growth
A2: 1 | B2: =VLOOKUP(C2,'List of economies'!$A$2:$D$219,4,FALSE) -> High income | C2: Qatar | D2: -0.13772537
A3: 1 | B3: =VLOOKUP(C3,'List of economies'!$A$2:$D$219,4,FALSE) -> Lower middle income | C3: Jordan | D3: -0.085681991
A4: 1 | B4: =VLOOKUP(C4,'List of economies'!$A$2:$D$219,4,FALSE) -> Upper middle income | C4: Algeria | D4: 0.071427344
A5: 1 | B5: =VLOOKUP(C5,'List of economies'!$A$2:$D$219,4,FALSE) -> Upper middle income | C5: El Salvador | D5: 0.22604105
A6: 1 | B6: =VLOOKUP(C6,'List of economies'!$A$2:$D$219,4,FALSE) -> Lower middle income | C6: Morocco | D6: 0.3323339
A7: 1 | B7: =VLOOKUP(C7,'List of economies'!$A$2:$D$219,4,FALSE) -> High income | C7: Latvia | D7: 0.38586813
B8: =VLOOKUP(C8,'List of economies'!$A$2:$D$219,4,FALSE) -> Upper middle income | C8: Ecuador | D8: 0.39200325
B9: =VLOOKUP(C9,'List of economies'!$A$2:$D$219,4,FALSE) -> Upper middle income | C9: Indonesia | D9: 0.45783236
A10: 1 | B10: =VLOOKUP(C10,'List of economies'!$A$2:$D$219,4,FALSE) -> High income | C10: Sweden | D10: 0.49231032
A11: 1 | B11: =VLOOKUP(C11,'List of economies'!$A$2:$D$219,4,FALSE) -> Upper middle income | C11: Kazakhstan | D11: 0.51021156
A12: 1 | B12: =VLOOKUP(C12,'List of economies'!$A$2:$D$219,4,FALSE) -> Upper middle income | C12: Belarus | D12: 0.51292143
A13: 1 | B13: =VLOOKUP(C13,'List of economies'!$A$2:$D$219,4,FALSE) -> High income | C13: Italy | D13: 0.52655885
A14: 1 | B14: =VLOOKUP(C14,'List of economies'!$A$2:$D$219,4,FALSE) -> Upper middle income | C14: Ukraine | D14: 0.53048734
B15: =VLOOKUP(C15,'List of economies'!$A$2:$D$219,4,FALSE) -> Upper middle income | C15: Mauritius | D15: 0.55173195
A16: 1 | B16: =VLOOKUP(C16,'List of economies'!$A$2:$D$219,4,FALSE) -> Upper middle income | C16: Moldova | D16: 0.56074104
A17: 1 | B17: =VLOOKUP(C17,'List of economies'!$A$2:$D$219,4,FALSE) -> Upper middle income | C17: North Macedonia | D17: 0.58023705
A18: 1 | B18: =VLOOKUP(C18,'List of economies'!$A$2:$D$219,4,FALSE) -> Upper middle income | C18: Montenegro | D18: 0.65013701
A19: 1 | B19: =VLOOKUP(C19,'List of economies'!$A$2:$D$219,4,FALSE) -> High income | C19: Spain | D19: 0.70787898
A20: 1 | B20: =VLOOKUP(C20,'List of economies'!$A$2:$D$219,4,FALSE) -> Upper middle income | C20: Georgia | D20: 0.70952057
A21: 1 | B21: =VLOOKUP(C21,'List of economies'!$A$2:$D$219,4,FALSE) -> Upper middle income | C21: Brazil | D21: 0.73307972
A22: 1 | B22: =VLOOKUP(C22,'List of economies'!$A$2:$D$219,4,FALSE) -> High income | C22: Oman | D22: 0.7704364
A23: 1 | B23: =VLOOKUP(C23,'List of economies'!$A$2:$D$219,4,FALSE) -> High income | C23: Romania | D23: 0.78540479
A24: 1 | B24: =VLOOKUP(C24,'List of economies'!$A$2:$D$219,4,FALSE) -> Lower middle income | C24: Uzbekistan | D24: 0.80908019
B25: =VLOOKUP(C25,'List of economies'!$A$2:$D$219,4,FALSE) -> Upper middle income | C25: Iraq | D25: 0.84159347
A26: 1 | B26: =VLOOKUP(C26,'List of economies'!$A$2:$D$219,4,FALSE) -> Upper middle income | C26: Serbia | D26: 0.884501
A27: 1 | B27: =VLOOKUP(C27,'List of economies'!$A$2:$D$219,4,FALSE) -> Upper middle income | C27: Azerbaijan | D27: 0.90720516
A28: 1 | B28: =VLOOKUP(C28,'List of economies'!$A$2:$D$219,4,FALSE) -> High income | C28: Lithuania | D28: 0.9243801
A29: 1 | B29: =VLOOKUP(C29,'List of economies'!$A$2:$D$219,4,FALSE) -> High income | C29: Estonia | D29: 0.95746811
A30: 1 | B30: =VLOOKUP(C30,'List of economies'!$A$2:$D$219,4,FALSE) -> High income | C30: Bulgaria | D30: 0.98171881
A31: 1 | B31: =VLOOKUP(C31,'List of economies'!$A$2:$D$219,4,FALSE) -> High income | C31: Saudi Arabia | D31: 1
A32: 1 | B32: =VLOOKUP(C32,'List of economies'!$A$2:$D$219,4,FALSE) -> Lower middle income | C32: Pakistan | D32: 1
A33: 1 | B33: =VLOOKUP(C33,'List of economies'!$A$2:$D$219,4,FALSE) -> High income | C33: Croatia | D33: 1.0433926
A34: 1 | B34: =VLOOKUP(C34,'List of economies'!$A$2:$D$219,4,FALSE) -> High income | C34: United Kingdom | D34: 1.0739748
A35: 1 | B35: =VLOOKUP(C35,'List of economies'!$A$2:$D$219,4,FALSE) -> High income | C35: Poland | D35: 1.0796903
A36: 1 | B36: =VLOOKUP(C36,'List of economies'!$A$2:$D$219,4,FALSE) -> Upper middle income | C36: Albania | D36: 1.0835676
A37: 1 | B37: =VLOOKUP(C37,'List of economies'!$A$2:$D$219,4,FALSE) -> Upper middle income | C37: Malaysia | D37: 1.0971715
B38: =VLOOKUP(C38,'List of economies'!$A$2:$D$219,4,FALSE) -> Upper middle income | C38: Bosnia And Herzegovina | D38: 1.1064672
B39: =VLOOKUP(C39,'List of economies'!$A$2:$D$219,4,FALSE) -> High income | C39: Panama | D39: 1.108481
A40: 1 | B40: =VLOOKUP(C40,'List of economies'!$A$2:$D$219,4,FALSE) -> High income | C40: Luxembourg | D40: 1.1172264
...

Sheet Sheet6
A1: Income group | B1: Country | C1: REP growth per income growth
A2: High income | B2: Qatar | C2: -0.13772537
A3: Lower middle income | B3: Jordan | C3: -0.085681991
A4: Upper middle income | B4: El Salvador | C4: 0.22604105
A5: High income | B5: Latvia | C5: 0.38586813
A6: High income | B6: Sweden | C6: 0.49231032
A7: Upper middle income | B7: Kazakhstan | C7: 0.51021156
A8: Upper middle income | B8: Belarus | C8: 0.51292143
A9: High income | B9: Italy | C9: 0.52655885
A10: Upper middle income | B10: Ukraine | C10: 0.53048734
A11: Upper middle income | B11: Moldova | C11: 0.56074104
A12: High income | B12: Spain | C12: 0.70787898
A13: Upper middle income | B13: Georgia | C13: 0.70952057
... A62: Upper middle income | B62: Mexico | C62: 4.2134544

Sheet Sheet1
B1: Income | C1: Price to income | D1: Price | E1: Income | F1: Price to income | G1: Price | H1: delta Price
B2: 1000 | C2: 1.5 | D2: =B2*C2 -> 1500 | E2: 2000 | F2: 2 | G2: =E2*F2 -> 4000 | H2: =G2/D2-1 -> 1.6666667

Sheet List of economies
A1: Economy | B1: Code | C1: Region | D1: Income group | E1: Lending category
A2: Afghanistan | B2: AFG | C2: Middle East, North Africa, Afghanistan & Pakistan | D2: Low income | E2: IDA
A3: Albania | B3: ALB | C3: Europe & Central Asia | D3: Upper middle income | E3: IBRD
A4: Algeria | B4: DZA | C4: Middle East, North Africa, Afghanistan & Pakistan | D4: Upper middle income | E4: IBRD
A5: American Samoa | B5: ASM | C5: East Asia & Pacific | D5: High income
A6: Andorra | B6: AND | C6: Europe & Central Asia | D6: High income
A7: Angola | B7: AGO | C7: Sub-Saharan Africa | D7: Lower middle income | E7: IBRD
A8: Antigua and Barbuda | B8: ATG | C8: Latin America & Caribbean | D8: High income | E8: IBRD
A9: Argentina | B9: ARG | C9: Latin America & Caribbean | D9: Upper middle income | E9: IBRD
A10: Armenia | B10: ARM | C10: Europe & Central Asia | D10: Upper middle income | E10: IBRD
A11: Aruba | B11: ABW | C11: Latin America & Caribbean | D11: High income
A12: Australia | B12: AUS | C12: East Asia & Pacific | D12: High income
A13: Austria | B13: AUT | C13: Europe & Central Asia | D13: High income
A14: Azerbaijan | B14: AZE | C14: Europe & Central Asia | D14: Upper middle income | E14: IBRD
A15: Bahamas, The | B15: BHS | C15: Latin America & Caribbean | D15: High income
A16: Bahrain | B16: BHR | C16: Middle East, North Africa, Afghanistan & Pakistan | D16: High income
A17: Bangladesh | B17: BGD | C17: South Asia | D17: Lower middle income | E17: IDA
A18: Barbados | B18: BRB | C18: Latin America & Caribbean | D18: High income | E18: IBRD
A19: Belarus | B19: BLR | C19: Europe & Central Asia | D19: Upper middle income | E19: IBRD
A20: Belgium | B20: BEL | C20: Europe & Central Asia | D20: High income
A21: Belize | B21: BLZ | C21: Latin America & Caribbean | D21: Upper middle income | E21: Blend
A22: Benin | B22: BEN | C22: Sub-Saharan Africa | D22: Lower middle income | E22: IDA
A23: Bermuda | B23: BMU | C23: North America | D23: High income
A24: Bhutan | B24: BTN | C24: South Asia | D24: Lower middle income | E24: IDA
A25: Bolivia | B25: BOL | C25: Latin America & Caribbean | D25: Lower middle income | E25: IBRD
A26: Bosnia and Herzegovina | B26: BIH | C26: Europe & Central Asia | D26: Upper middle income | E26: IBRD
A27: Botswana | B27: BWA | C27: Sub-Saharan Africa | D27: Upper middle income | E27: IBRD
A28: Brazil | B28: BRA | C28: Latin America & Caribbean | D28: Upper middle income | E28: IBRD
A29: British Virgin Islands | B29: VGB | C29: Latin America & Caribbean | D29: High income
A30: Brunei Darussalam | B30: BRN | C30: East Asia & Pacific | D30: High income
A31: Bulgaria | B31: BGR | C31: Europe & Central Asia | D31: High income | E31: IBRD
A32: Burkina Faso | B32: BFA | C32: Sub-Saharan Africa | D32: Low income | E32: IDA
A33: Burundi | B33: BDI | C33: Sub-Saharan Africa | D33: Low income | E33: IDA
A34: Cabo Verde | B34: CPV | C34: Sub-Saharan Africa | D34: Upper middle income | E34: Blend
A35: Cambodia | B35: KHM | C35: East Asia & Pacific | D35: Lower middle income | E35: IDA
A36: Cameroon | B36: CMR | C36: Sub-Saharan Africa | D36: Lower middle income | E36: Blend
A37: Canada | B37: CAN | C37: North America | D37: High income
A38: Cayman Islands | B38: CYM | C38: Latin America & Caribbean | D38: High income
A39: Central African Republic | B39: CAF | C39: Sub-Saharan Africa | D39: Low income | E39: IDA
A40: Chad | B40: TCD | C40: Sub-Saharan Africa | D40: Low income | E40: IDA
...
