Workbook

Sheet Sheet1
A1: Country Code | B1: year | C1: credit_to_gdp | D1: year_thr1 | E1: year_thr2 | F1: year count
A2: AUS | B2: 1989 | C2: 0.59177453 | D2: 1989 | E2: 2004 | F2: =COUNTIFS($A$2:A2, A2) -> 1 | H2: Country | I2: 1 | J2: 2 | K2: 3 | L2: 4 | M2: 5 | N2: 6 | O2: 7 | P2: 8 | Q2: 9 | R2: 10 | S2: 11 | T2: 12 | U2: 13 | V2: 14 | W2: 15 | X2: 16 | Y2: 17 | Z2: 18 | AA2: 19 | AB2: 20 | AC2: 21 | AD2: 22 | AE2: 23 | AF2: 24 | AG2: 25 | AH2: 26 | AI2: 27 | AJ2: 28 | AK2: 29 | AL2: 30 | AM2: 31 | AN2: 32 | AO2: 33 | AP2: 34 | AQ2: 35
A3: AUS | B3: 1990 | C3: 0.60475371 | D3: 1989 | E3: 2004 | F3: =COUNTIFS($A$2:A3, A3) -> 2 | H3: AUS | I3: =IFERROR(AVERAGEIFS($C$2:$C$604,$A$2:$A$604,$H3,$F$2:$F$604,I$2),"") -> 0.59177453 | J3: =IFERROR(AVERAGEIFS($C$2:$C$604,$A$2:$A$604,$H3,$F$2:$F$604,J$2),"") -> 0.60475371 | K3: =IFERROR(AVERAGEIFS($C$2:$C$604,$A$2:$A$604,$H3,$F$2:$F$604,K$2),"") -> 0.60033374 | L3: =IFERROR(AVERAGEIFS($C$2:$C$604,$A$2:$A$604,$H3,$F$2:$F$604,L$2),"") -> 0.61773309 | M3: =IFERROR(AVERAGEIFS($C$2:$C$604,$A$2:$A$604,$H3,$F$2:$F$604,M$2),"") -> 0.63192072 | N3: =IFERROR(AVERAGEIFS($C$2:$C$604,$A$2:$A$604,$H3,$F$2:$F$604,N$2),"") -> 0.66673424 | O3: =IFERROR(AVERAGEIFS($C$2:$C$604,$A$2:$A$604,$H3,$F$2:$F$604,O$2),"") -> 0.6966795 | P3: =IFERROR(AVERAGEIFS($C$2:$C$604,$A$2:$A$604,$H3,$F$2:$F$604,P$2),"") -> 0.71386377 | ... X3: =IFERROR(AVERAGEIFS($C$2:$C$604,$A$2:$A$604,$H3,$F$2:$F$604,X$2),"") -> 1.0244769
A4: AUS | B4: 1991 | C4: 0.60033374 | D4: 1989 | E4: 2004 | F4: =COUNTIFS($A$2:A4, A4) -> 3 | H4: BRA | I4: =IFERROR(AVERAGEIFS($C$2:$C$604,$A$2:$A$604,$H4,$F$2:$F$604,I$2),"") -> 0.52595594 | J4: =IFERROR(AVERAGEIFS($C$2:$C$604,$A$2:$A$604,$H4,$F$2:$F$604,J$2),"") -> 0.54468795 | K4: =IFERROR(AVERAGEIFS($C$2:$C$604,$A$2:$A$604,$H4,$F$2:$F$604,K$2),"") -> 0.54392781 | L4: =IFERROR(AVERAGEIFS($C$2:$C$604,$A$2:$A$604,$H4,$F$2:$F$604,L$2),"") -> 0.50425107 | M4: =IFERROR(AVERAGEIFS($C$2:$C$604,$A$2:$A$604,$H4,$F$2:$F$604,M$2),"") -> 0.51012911 | N4: =IFERROR(AVERAGEIFS($C$2:$C$604,$A$2:$A$604,$H4,$F$2:$F$604,N$2),"") -> 0.42053738 | O4: =IFERROR(AVERAGEIFS($C$2:$C$604,$A$2:$A$604,$H4,$F$2:$F$604,O$2),"") -> 0.44691434 | P4: =IFERROR(AVERAGEIFS($C$2:$C$604,$A$2:$A$604,$H4,$F$2:$F$604,P$2),"") -> 0.45652572 | ... T4: =IFERROR(AVERAGEIFS($C$2:$C$604,$A$2:$A$604,$H4,$F$2:$F$604,T$2),"") -> 1.0539101
A5: AUS | B5: 1992 | C5: 0.61773309 | D5: 1989 | E5: 2004 | F5: =COUNTIFS($A$2:A5, A5) -> 4 | H5: CAN | I5: =IFERROR(AVERAGEIFS($C$2:$C$604,$A$2:$A$604,$H5,$F$2:$F$604,I$2),"") -> 0.53032184 | J5: =IFERROR(AVERAGEIFS($C$2:$C$604,$A$2:$A$604,$H5,$F$2:$F$604,J$2),"") -> 0.55675991 | K5: =IFERROR(AVERAGEIFS($C$2:$C$604,$A$2:$A$604,$H5,$F$2:$F$604,K$2),"") -> 0.56416627 | L5: =IFERROR(AVERAGEIFS($C$2:$C$604,$A$2:$A$604,$H5,$F$2:$F$604,L$2),"") -> 0.69870344 | M5: =IFERROR(AVERAGEIFS($C$2:$C$604,$A$2:$A$604,$H5,$F$2:$F$604,M$2),"") -> 0.68063867 | N5: =IFERROR(AVERAGEIFS($C$2:$C$604,$A$2:$A$604,$H5,$F$2:$F$604,N$2),"") -> 0.63007339 | O5: =IFERROR(AVERAGEIFS($C$2:$C$604,$A$2:$A$604,$H5,$F$2:$F$604,O$2),"") -> 0.62618781 | P5: =IFERROR(AVERAGEIFS($C$2:$C$604,$A$2:$A$604,$H5,$F$2:$F$604,P$2),"") -> 0.63228586 | ... AF5: =IFERROR(AVERAGEIFS($C$2:$C$604,$A$2:$A$604,$H5,$F$2:$F$604,AF$2),"") -> 1.2135283
A6: AUS | B6: 1993 | C6: 0.63192072 | D6: 1989 | E6: 2004 | F6: =COUNTIFS($A$2:A6, A6) -> 5 | H6: CHN | I6: =IFERROR(AVERAGEIFS($C$2:$C$604,$A$2:$A$604,$H6,$F$2:$F$604,I$2),"") -> 0.51093568 | J6: =IFERROR(AVERAGEIFS($C$2:$C$604,$A$2:$A$604,$H6,$F$2:$F$604,J$2),"") -> 0.50206253 | K6: =IFERROR(AVERAGEIFS($C$2:$C$604,$A$2:$A$604,$H6,$F$2:$F$604,K$2),"") -> 0.49659135 | L6: =IFERROR(AVERAGEIFS($C$2:$C$604,$A$2:$A$604,$H6,$F$2:$F$604,L$2),"") -> 0.5253389 | M6: =IFERROR(AVERAGEIFS($C$2:$C$604,$A$2:$A$604,$H6,$F$2:$F$604,M$2),"") -> 0.55912391 | N6: =IFERROR(AVERAGEIFS($C$2:$C$604,$A$2:$A$604,$H6,$F$2:$F$604,N$2),"") -> 0.56696263 | O6: =IFERROR(AVERAGEIFS($C$2:$C$604,$A$2:$A$604,$H6,$F$2:$F$604,O$2),"") -> 0.56876917 | P6: =IFERROR(AVERAGEIFS($C$2:$C$604,$A$2:$A$604,$H6,$F$2:$F$604,P$2),"") -> 0.60605562 | ... AD6: =IFERROR(AVERAGEIFS($C$2:$C$604,$A$2:$A$604,$H6,$F$2:$F$604,AD$2),"") -> 1.0437436
A7: AUS | B7: 1994 | C7: 0.66673424 | D7: 1989 | E7: 2004 | F7: =COUNTIFS($A$2:A7, A7) -> 6 | H7: DNK | I7: =IFERROR(AVERAGEIFS($C$2:$C$604,$A$2:$A$604,$H7,$F$2:$F$604,I$2),"") -> 0.54842236 | J7: =IFERROR(AVERAGEIFS($C$2:$C$604,$A$2:$A$604,$H7,$F$2:$F$604,J$2),"") -> 0.49720323 | K7: =IFERROR(AVERAGEIFS($C$2:$C$604,$A$2:$A$604,$H7,$F$2:$F$604,K$2),"") -> 0.47898527 | L7: =IFERROR(AVERAGEIFS($C$2:$C$604,$A$2:$A$604,$H7,$F$2:$F$604,L$2),"") -> 0.50797135 | M7: =IFERROR(AVERAGEIFS($C$2:$C$604,$A$2:$A$604,$H7,$F$2:$F$604,M$2),"") -> 0.50341353 | N7: =IFERROR(AVERAGEIFS($C$2:$C$604,$A$2:$A$604,$H7,$F$2:$F$604,N$2),"") -> 0.41882102 | O7: =IFERROR(AVERAGEIFS($C$2:$C$604,$A$2:$A$604,$H7,$F$2:$F$604,O$2),"") -> 0.39331498 | P7: =IFERROR(AVERAGEIFS($C$2:$C$604,$A$2:$A$604,$H7,$F$2:$F$604,P$2),"") -> 0.34261036 | ... W7: =IFERROR(AVERAGEIFS($C$2:$C$604,$A$2:$A$604,$H7,$F$2:$F$604,W$2),"") -> 1.3206094
A8: AUS | B8: 1995 | C8: 0.6966795 | D8: 1989 | E8: 2004 | F8: =COUNTIFS($A$2:A8, A8) -> 7 | H8: EAP | I8: =IFERROR(AVERAGEIFS($C$2:$C$604,$A$2:$A$604,$H8,$F$2:$F$604,I$2),"") -> 0.51678539 | J8: =IFERROR(AVERAGEIFS($C$2:$C$604,$A$2:$A$604,$H8,$F$2:$F$604,J$2),"") -> 0.5279499 | K8: =IFERROR(AVERAGEIFS($C$2:$C$604,$A$2:$A$604,$H8,$F$2:$F$604,K$2),"") -> 0.54854408 | L8: =IFERROR(AVERAGEIFS($C$2:$C$604,$A$2:$A$604,$H8,$F$2:$F$604,L$2),"") -> 0.57594762 | M8: =IFERROR(AVERAGEIFS($C$2:$C$604,$A$2:$A$604,$H8,$F$2:$F$604,M$2),"") -> 0.63144843 | N8: =IFERROR(AVERAGEIFS($C$2:$C$604,$A$2:$A$604,$H8,$F$2:$F$604,N$2),"") -> 0.71586651 | O8: =IFERROR(AVERAGEIFS($C$2:$C$604,$A$2:$A$604,$H8,$F$2:$F$604,O$2),"") -> 0.68116983 | P8: =IFERROR(AVERAGEIFS($C$2:$C$604,$A$2:$A$604,$H8,$F$2:$F$604,P$2),"") -> 0.71317072 | ... Y8: =IFERROR(AVERAGEIFS($C$2:$C$604,$A$2:$A$604,$H8,$F$2:$F$604,Y$2),"") -> 1.0089026
A9: AUS | B9: 1996 | C9: 0.71386377 | D9: 1989 | E9: 2004 | F9: =COUNTIFS($A$2:A9, A9) -> 8 | H9: EST | I9: =IFERROR(AVERAGEIFS($C$2:$C$604,$A$2:$A$604,$H9,$F$2:$F$604,I$2),"") -> 0.56573909 | J9: =IFERROR(AVERAGEIFS($C$2:$C$604,$A$2:$A$604,$H9,$F$2:$F$604,J$2),"") -> 0.76224565 | K9: =IFERROR(AVERAGEIFS($C$2:$C$604,$A$2:$A$604,$H9,$F$2:$F$604,K$2),"") -> 0.83747613 | L9: =IFERROR(AVERAGEIFS($C$2:$C$604,$A$2:$A$604,$H9,$F$2:$F$604,L$2),"") -> 0.89668873 | M9: =IFERROR(AVERAGEIFS($C$2:$C$604,$A$2:$A$604,$H9,$F$2:$F$604,M$2),"") -> 1.0138303
A10: AUS | B10: 1997 | C10: 0.7520147 | D10: 1989 | E10: 2004 | F10: =COUNTIFS($A$2:A10, A10) -> 9 | H10: FIN | I10: =IFERROR(AVERAGEIFS($C$2:$C$604,$A$2:$A$604,$H10,$F$2:$F$604,I$2),"") -> 0.52654566 | J10: =IFERROR(AVERAGEIFS($C$2:$C$604,$A$2:$A$604,$H10,$F$2:$F$604,J$2),"") -> 0.55436378 | K10: =IFERROR(AVERAGEIFS($C$2:$C$604,$A$2:$A$604,$H10,$F$2:$F$604,K$2),"") -> 0.60284483 | L10: =IFERROR(AVERAGEIFS($C$2:$C$604,$A$2:$A$604,$H10,$F$2:$F$604,L$2),"") -> 0.63732747 | M10: =IFERROR(AVERAGEIFS($C$2:$C$604,$A$2:$A$604,$H10,$F$2:$F$604,M$2),"") -> 0.69254734 | N10: =IFERROR(AVERAGEIFS($C$2:$C$604,$A$2:$A$604,$H10,$F$2:$F$604,N$2),"") -> 0.73413899 | O10: =IFERROR(AVERAGEIFS($C$2:$C$604,$A$2:$A$604,$H10,$F$2:$F$604,O$2),"") -> 0.76282884 | P10: =IFERROR(AVERAGEIFS($C$2:$C$604,$A$2:$A$604,$H10,$F$2:$F$604,P$2),"") -> 0.80105327 | ... AB10: =IFERROR(AVERAGEIFS($C$2:$C$604,$A$2:$A$604,$H10,$F$2:$F$604,AB$2),"") -> 1.0173825
A11: AUS | B11: 1998 | C11: 0.78974896 | D11: 1989 | E11: 2004 | F11: =COUNTIFS($A$2:A11, A11) -> 10 | H11: FJI | I11: =IFERROR(AVERAGEIFS($C$2:$C$604,$A$2:$A$604,$H11,$F$2:$F$604,I$2),"") -> 0.55299121 | J11: =IFERROR(AVERAGEIFS($C$2:$C$604,$A$2:$A$604,$H11,$F$2:$F$604,J$2),"") -> 0.54742556 | K11: =IFERROR(AVERAGEIFS($C$2:$C$604,$A$2:$A$604,$H11,$F$2:$F$604,K$2),"") -> 0.61113472 | L11: =IFERROR(AVERAGEIFS($C$2:$C$604,$A$2:$A$604,$H11,$F$2:$F$604,L$2),"") -> 0.69191585 | M11: =IFERROR(AVERAGEIFS($C$2:$C$604,$A$2:$A$604,$H11,$F$2:$F$604,M$2),"") -> 0.79066689 | N11: =IFERROR(AVERAGEIFS($C$2:$C$604,$A$2:$A$604,$H11,$F$2:$F$604,N$2),"") -> 0.78749678 | O11: =IFERROR(AVERAGEIFS($C$2:$C$604,$A$2:$A$604,$H11,$F$2:$F$604,O$2),"") -> 0.85911351 | P11: =IFERROR(AVERAGEIFS($C$2:$C$604,$A$2:$A$604,$H11,$F$2:$F$604,P$2),"") -> 0.89605567 | ... Z11: =IFERROR(AVERAGEIFS($C$2:$C$604,$A$2:$A$604,$H11,$F$2:$F$604,Z$2),"") -> 1.0411388
A12: AUS | B12: 1999 | C12: 0.83904699 | D12: 1989 | E12: 2004 | F12: =COUNTIFS($A$2:A12, A12) -> 11 | H12: GRC | I12: =IFERROR(AVERAGEIFS($C$2:$C$604,$A$2:$A$604,$H12,$F$2:$F$604,I$2),"") -> 0.51696591 | J12: =IFERROR(AVERAGEIFS($C$2:$C$604,$A$2:$A$604,$H12,$F$2:$F$604,J$2),"") -> 0.54871833 | K12: =IFERROR(AVERAGEIFS($C$2:$C$604,$A$2:$A$604,$H12,$F$2:$F$604,K$2),"") -> 0.58731961 | L12: =IFERROR(AVERAGEIFS($C$2:$C$604,$A$2:$A$604,$H12,$F$2:$F$604,L$2),"") -> 0.63877543 | M12: =IFERROR(AVERAGEIFS($C$2:$C$604,$A$2:$A$604,$H12,$F$2:$F$604,M$2),"") -> 0.73657396 | N12: =IFERROR(AVERAGEIFS($C$2:$C$604,$A$2:$A$604,$H12,$F$2:$F$604,N$2),"") -> 0.77545437 | O12: =IFERROR(AVERAGEIFS($C$2:$C$604,$A$2:$A$604,$H12,$F$2:$F$604,O$2),"") -> 0.85798424 | P12: =IFERROR(AVERAGEIFS($C$2:$C$604,$A$2:$A$604,$H12,$F$2:$F$604,P$2),"") -> 0.90507314 | ... R12: =IFERROR(AVERAGEIFS($C$2:$C$604,$A$2:$A$604,$H12,$F$2:$F$604,R$2),"") -> 1.1281428
A13: AUS | B13: 2000 | C13: 0.87381033 | D13: 1989 | E13: 2004 | F13: =COUNTIFS($A$2:A13, A13) -> 12 | H13: HIC | I13: =IFERROR(AVERAGEIFS($C$2:$C$604,$A$2:$A$604,$H13,$F$2:$F$604,I$2),"") -> 0.59566198 | J13: =IFERROR(AVERAGEIFS($C$2:$C$604,$A$2:$A$604,$H13,$F$2:$F$604,J$2),"") -> 0.62709509 | K13: =IFERROR(AVERAGEIFS($C$2:$C$604,$A$2:$A$604,$H13,$F$2:$F$604,K$2),"") -> 0.63352525 | L13: =IFERROR(AVERAGEIFS($C$2:$C$604,$A$2:$A$604,$H13,$F$2:$F$604,L$2),"") -> 0.77510484 | M13: =IFERROR(AVERAGEIFS($C$2:$C$604,$A$2:$A$604,$H13,$F$2:$F$604,M$2),"") -> 0.81130873 | N13: =IFERROR(AVERAGEIFS($C$2:$C$604,$A$2:$A$604,$H13,$F$2:$F$604,N$2),"") -> 0.8662968 | O13: =IFERROR(AVERAGEIFS($C$2:$C$604,$A$2:$A$604,$H13,$F$2:$F$604,O$2),"") -> 0.83777606 | P13: =IFERROR(AVERAGEIFS($C$2:$C$604,$A$2:$A$604,$H13,$F$2:$F$604,P$2),"") -> 0.87168824 | ... T13: =IFERROR(AVERAGEIFS($C$2:$C$604,$A$2:$A$604,$H13,$F$2:$F$604,T$2),"") -> 1.0962072
A14: AUS | B14: 2001 | C14: 0.88189283 | D14: 1989 | E14: 2004 | F14: =COUNTIFS($A$2:A14, A14) -> 13 | H14: IBD | I14: =IFERROR(AVERAGEIFS($C$2:$C$604,$A$2:$A$604,$H14,$F$2:$F$604,I$2),"") -> 0.52217992 | J14: =IFERROR(AVERAGEIFS($C$2:$C$604,$A$2:$A$604,$H14,$F$2:$F$604,J$2),"") -> 0.52643577 | K14: =IFERROR(AVERAGEIFS($C$2:$C$604,$A$2:$A$604,$H14,$F$2:$F$604,K$2),"") -> 0.50782132 | L14: =IFERROR(AVERAGEIFS($C$2:$C$604,$A$2:$A$604,$H14,$F$2:$F$604,L$2),"") -> 0.54539585 | M14: =IFERROR(AVERAGEIFS($C$2:$C$604,$A$2:$A$604,$H14,$F$2:$F$604,M$2),"") -> 0.58138825 | N14: =IFERROR(AVERAGEIFS($C$2:$C$604,$A$2:$A$604,$H14,$F$2:$F$604,N$2),"") -> 0.57333968 | O14: =IFERROR(AVERAGEIFS($C$2:$C$604,$A$2:$A$604,$H14,$F$2:$F$604,O$2),"") -> 0.55959342 | P14: =IFERROR(AVERAGEIFS($C$2:$C$604,$A$2:$A$604,$H14,$F$2:$F$604,P$2),"") -> 0.57808062 | ... AB14: =IFERROR(AVERAGEIFS($C$2:$C$604,$A$2:$A$604,$H14,$F$2:$F$604,AB$2),"") -> 1.0347022
A15: AUS | B15: 2002 | C15: 0.9106854 | D15: 1989 | E15: 2004 | F15: =COUNTIFS($A$2:A15, A15) -> 14 | H15: IBT | I15: =IFERROR(AVERAGEIFS($C$2:$C$604,$A$2:$A$604,$H15,$F$2:$F$604,I$2),"") -> 0.50968485 | J15: =IFERROR(AVERAGEIFS($C$2:$C$604,$A$2:$A$604,$H15,$F$2:$F$604,J$2),"") -> 0.54209467 | K15: =IFERROR(AVERAGEIFS($C$2:$C$604,$A$2:$A$604,$H15,$F$2:$F$604,K$2),"") -> 0.53603608 | L15: =IFERROR(AVERAGEIFS($C$2:$C$604,$A$2:$A$604,$H15,$F$2:$F$604,L$2),"") -> 0.52463712 | M15: =IFERROR(AVERAGEIFS($C$2:$C$604,$A$2:$A$604,$H15,$F$2:$F$604,M$2),"") -> 0.54149668 | N15: =IFERROR(AVERAGEIFS($C$2:$C$604,$A$2:$A$604,$H15,$F$2:$F$604,N$2),"") -> 0.57366148 | O15: =IFERROR(AVERAGEIFS($C$2:$C$604,$A$2:$A$604,$H15,$F$2:$F$604,O$2),"") -> 0.57417863 | P15: =IFERROR(AVERAGEIFS($C$2:$C$604,$A$2:$A$604,$H15,$F$2:$F$604,P$2),"") -> 0.66697626 | ... AA15: =IFERROR(AVERAGEIFS($C$2:$C$604,$A$2:$A$604,$H15,$F$2:$F$604,AA$2),"") -> 1.1293207
A16: AUS | B16: 2003 | C16: 0.9897007 | D16: 1989 | E16: 2004 | F16: =COUNTIFS($A$2:A16, A16) -> 15 | H16: ISL | I16: =IFERROR(AVERAGEIFS($C$2:$C$604,$A$2:$A$604,$H16,$F$2:$F$604,I$2),"") -> 0.6378922 | J16: =IFERROR(AVERAGEIFS($C$2:$C$604,$A$2:$A$604,$H16,$F$2:$F$604,J$2),"") -> 0.6140587 | K16: =IFERROR(AVERAGEIFS($C$2:$C$604,$A$2:$A$604,$H16,$F$2:$F$604,K$2),"") -> 0.69988927 | L16: =IFERROR(AVERAGEIFS($C$2:$C$604,$A$2:$A$604,$H16,$F$2:$F$604,L$2),"") -> 0.9235795 | M16: =IFERROR(AVERAGEIFS($C$2:$C$604,$A$2:$A$604,$H16,$F$2:$F$604,M$2),"") -> 0.94088912 | N16: =IFERROR(AVERAGEIFS($C$2:$C$604,$A$2:$A$604,$H16,$F$2:$F$604,N$2),"") -> 0.99511217 | O16: =IFERROR(AVERAGEIFS($C$2:$C$604,$A$2:$A$604,$H16,$F$2:$F$604,O$2),"") -> 1.236804
A17: AUS | B17: 2004 | C17: 1.0244769 | D17: 1989 | E17: 2004 | F17: =COUNTIFS($A$2:A17, A17) -> 16 | H17: KHM | I17: =IFERROR(AVERAGEIFS($C$2:$C$604,$A$2:$A$604,$H17,$F$2:$F$604,I$2),"") -> 0.55489548 | J17: =IFERROR(AVERAGEIFS($C$2:$C$604,$A$2:$A$604,$H17,$F$2:$F$604,J$2),"") -> 0.61560889 | K17: =IFERROR(AVERAGEIFS($C$2:$C$604,$A$2:$A$604,$H17,$F$2:$F$604,K$2),"") -> 0.65462721 | L17: =IFERROR(AVERAGEIFS($C$2:$C$604,$A$2:$A$604,$H17,$F$2:$F$604,L$2),"") -> 0.73816427 | M17: =IFERROR(AVERAGEIFS($C$2:$C$604,$A$2:$A$604,$H17,$F$2:$F$604,M$2),"") -> 0.84323674 | N17: =IFERROR(AVERAGEIFS($C$2:$C$604,$A$2:$A$604,$H17,$F$2:$F$604,N$2),"") -> 1.0373277
A18: BRA | B18: 1975 | C18: 0.52595594 | D18: 1975 | E18: 1988 | F18: =COUNTIFS($A$2:A18, A18) -> 1 | H18: KOR | I18: =IFERROR(AVERAGEIFS($C$2:$C$604,$A$2:$A$604,$H18,$F$2:$F$604,I$2),"") -> 0.50146287 | J18: =IFERROR(AVERAGEIFS($C$2:$C$604,$A$2:$A$604,$H18,$F$2:$F$604,J$2),"") -> 0.54801785 | K18: =IFERROR(AVERAGEIFS($C$2:$C$604,$A$2:$A$604,$H18,$F$2:$F$604,K$2),"") -> 0.59608694 | L18: =IFERROR(AVERAGEIFS($C$2:$C$604,$A$2:$A$604,$H18,$F$2:$F$604,L$2),"") -> 0.64488126 | M18: =IFERROR(AVERAGEIFS($C$2:$C$604,$A$2:$A$604,$H18,$F$2:$F$604,M$2),"") -> 0.69186672 | N18: =IFERROR(AVERAGEIFS($C$2:$C$604,$A$2:$A$604,$H18,$F$2:$F$604,N$2),"") -> 0.99608241 | O18: =IFERROR(AVERAGEIFS($C$2:$C$604,$A$2:$A$604,$H18,$F$2:$F$604,O$2),"") -> 1.0870538
A19: BRA | B19: 1976 | C19: 0.54468795 | D19: 1975 | E19: 1988 | F19: =COUNTIFS($A$2:A19, A19) -> 2 | H19: KWT | I19: =IFERROR(AVERAGEIFS($C$2:$C$604,$A$2:$A$604,$H19,$F$2:$F$604,I$2),"") -> 0.52439232 | J19: =IFERROR(AVERAGEIFS($C$2:$C$604,$A$2:$A$604,$H19,$F$2:$F$604,J$2),"") -> 0.72187437 | K19: =IFERROR(AVERAGEIFS($C$2:$C$604,$A$2:$A$604,$H19,$F$2:$F$604,K$2),"") -> 0.71785041 | L19: =IFERROR(AVERAGEIFS($C$2:$C$604,$A$2:$A$604,$H19,$F$2:$F$604,L$2),"") -> 0.72431308 | M19: =IFERROR(AVERAGEIFS($C$2:$C$604,$A$2:$A$604,$H19,$F$2:$F$604,M$2),"") -> 0.7342704 | N19: =IFERROR(AVERAGEIFS($C$2:$C$604,$A$2:$A$604,$H19,$F$2:$F$604,N$2),"") -> 0.93545605 | O19: =IFERROR(AVERAGEIFS($C$2:$C$604,$A$2:$A$604,$H19,$F$2:$F$604,O$2),"") -> 0.83021432 | P19: =IFERROR(AVERAGEIFS($C$2:$C$604,$A$2:$A$604,$H19,$F$2:$F$604,P$2),"") -> 0.90845633 | ... AQ19: =IFERROR(AVERAGEIFS($C$2:$C$604,$A$2:$A$604,$H19,$F$2:$F$604,AQ$2),"") -> 1.0518681
A20: BRA | B20: 1977 | C20: 0.54392781 | D20: 1975 | E20: 1988 | F20: =COUNTIFS($A$2:A20, A20) -> 3 | H20: LBN | I20: =IFERROR(AVERAGEIFS($C$2:$C$604,$A$2:$A$604,$H20,$F$2:$F$604,I$2),"") -> 0.54550737 | J20: =IFERROR(AVERAGEIFS($C$2:$C$604,$A$2:$A$604,$H20,$F$2:$F$604,J$2),"") -> 0.65548294 | K20: =IFERROR(AVERAGEIFS($C$2:$C$604,$A$2:$A$604,$H20,$F$2:$F$604,K$2),"") -> 0.79377498 | L20: =IFERROR(AVERAGEIFS($C$2:$C$604,$A$2:$A$604,$H20,$F$2:$F$604,L$2),"") -> 0.45735857 | M20: =IFERROR(AVERAGEIFS($C$2:$C$604,$A$2:$A$604,$H20,$F$2:$F$604,M$2),"") -> 0.48948358 | N20: =IFERROR(AVERAGEIFS($C$2:$C$604,$A$2:$A$604,$H20,$F$2:$F$604,N$2),"") -> 0.42968592 | O20: =IFERROR(AVERAGEIFS($C$2:$C$604,$A$2:$A$604,$H20,$F$2:$F$604,O$2),"") -> 0.48816396 | P20: =IFERROR(AVERAGEIFS($C$2:$C$604,$A$2:$A$604,$H20,$F$2:$F$604,P$2),"") -> 0.54944633 | ... AJ20: =IFERROR(AVERAGEIFS($C$2:$C$604,$A$2:$A$604,$H20,$F$2:$F$604,AJ$2),"") -> 1.0056612
A21: BRA | B21: 1978 | C21: 0.50425107 | D21: 1975 | E21: 1988 | F21: =COUNTIFS($A$2:A21, A21) -> 4 | H21: LMY | I21: =IFERROR(AVERAGEIFS($C$2:$C$604,$A$2:$A$604,$H21,$F$2:$F$604,I$2),"") -> 0.61304163 | J21: =IFERROR(AVERAGEIFS($C$2:$C$604,$A$2:$A$604,$H21,$F$2:$F$604,J$2),"") -> 0.48584998 | K21: =IFERROR(AVERAGEIFS($C$2:$C$604,$A$2:$A$604,$H21,$F$2:$F$604,K$2),"") -> 0.50852522 | L21: =IFERROR(AVERAGEIFS($C$2:$C$604,$A$2:$A$604,$H21,$F$2:$F$604,L$2),"") -> 0.47029401 | M21: =IFERROR(AVERAGEIFS($C$2:$C$604,$A$2:$A$604,$H21,$F$2:$F$604,M$2),"") -> 0.48474739 | N21: =IFERROR(AVERAGEIFS($C$2:$C$604,$A$2:$A$604,$H21,$F$2:$F$604,N$2),"") -> 0.47719072 | O21: =IFERROR(AVERAGEIFS($C$2:$C$604,$A$2:$A$604,$H21,$F$2:$F$604,O$2),"") -> 0.47063182 | P21: =IFERROR(AVERAGEIFS($C$2:$C$604,$A$2:$A$604,$H21,$F$2:$F$604,P$2),"") -> 0.51566497 | ... AI21: =IFERROR(AVERAGEIFS($C$2:$C$604,$A$2:$A$604,$H21,$F$2:$F$604,AI$2),"") -> 1.023168
A22: BRA | B22: 1979 | C22: 0.51012911 | D22: 1975 | E22: 1988 | F22: =COUNTIFS($A$2:A22, A22) -> 5 | H22: LTE | I22: =IFERROR(AVERAGEIFS($C$2:$C$604,$A$2:$A$604,$H22,$F$2:$F$604,I$2),"") -> 0.52436949 | J22: =IFERROR(AVERAGEIFS($C$2:$C$604,$A$2:$A$604,$H22,$F$2:$F$604,J$2),"") -> 0.54615397 | K22: =IFERROR(AVERAGEIFS($C$2:$C$604,$A$2:$A$604,$H22,$F$2:$F$604,K$2),"") -> 0.56183174 | L22: =IFERROR(AVERAGEIFS($C$2:$C$604,$A$2:$A$604,$H22,$F$2:$F$604,L$2),"") -> 0.60548447 | M22: =IFERROR(AVERAGEIFS($C$2:$C$604,$A$2:$A$604,$H22,$F$2:$F$604,M$2),"") -> 0.6460444 | N22: =IFERROR(AVERAGEIFS($C$2:$C$604,$A$2:$A$604,$H22,$F$2:$F$604,N$2),"") -> 0.64574588 | O22: =IFERROR(AVERAGEIFS($C$2:$C$604,$A$2:$A$604,$H22,$F$2:$F$604,O$2),"") -> 0.72639419 | P22: =IFERROR(AVERAGEIFS($C$2:$C$604,$A$2:$A$604,$H22,$F$2:$F$604,P$2),"") -> 0.73410899 | ... AC22: =IFERROR(AVERAGEIFS($C$2:$C$604,$A$2:$A$604,$H22,$F$2:$F$604,AC$2),"") -> 1.0037035
A23: BRA | B23: 1980 | C23: 0.42053738 | D23: 1975 | E23: 1988 | F23: =COUNTIFS($A$2:A23, A23) -> 6 | H23: MAC | I23: =IFERROR(AVERAGEIFS($C$2:$C$604,$A$2:$A$604,$H23,$F$2:$F$604,I$2),"") -> 0.52428203 | J23: =IFERROR(AVERAGEIFS($C$2:$C$604,$A$2:$A$604,$H23,$F$2:$F$604,J$2),"") -> 0.63188619 | K23: =IFERROR(AVERAGEIFS($C$2:$C$604,$A$2:$A$604,$H23,$F$2:$F$604,K$2),"") -> 0.61091472 | L23: =IFERROR(AVERAGEIFS($C$2:$C$604,$A$2:$A$604,$H23,$F$2:$F$604,L$2),"") -> 0.56016836 | M23: =IFERROR(AVERAGEIFS($C$2:$C$604,$A$2:$A$604,$H23,$F$2:$F$604,M$2),"") -> 0.59636472 | N23: =IFERROR(AVERAGEIFS($C$2:$C$604,$A$2:$A$604,$H23,$F$2:$F$604,N$2),"") -> 0.63597553 | O23: =IFERROR(AVERAGEIFS($C$2:$C$604,$A$2:$A$604,$H23,$F$2:$F$604,O$2),"") -> 0.62642857 | P23: =IFERROR(AVERAGEIFS($C$2:$C$604,$A$2:$A$604,$H23,$F$2:$F$604,P$2),"") -> 0.65594266 | ... AN23: =IFERROR(AVERAGEIFS($C$2:$C$604,$A$2:$A$604,$H23,$F$2:$F$604,AN$2),"") -> 1.085117
A24: BRA | B24: 1981 | C24: 0.44691434 | D24: 1975 | E24: 1988 | F24: =COUNTIFS($A$2:A24, A24) -> 7 | H24: MIC | I24: =IFERROR(AVERAGEIFS($C$2:$C$604,$A$2:$A$604,$H24,$F$2:$F$604,I$2),"") -> 0.51409687 | J24: =IFERROR(AVERAGEIFS($C$2:$C$604,$A$2:$A$604,$H24,$F$2:$F$604,J$2),"") -> 0.63239913 | K24: =IFERROR(AVERAGEIFS($C$2:$C$604,$A$2:$A$604,$H24,$F$2:$F$604,K$2),"") -> 0.50057896 | L24: =IFERROR(AVERAGEIFS($C$2:$C$604,$A$2:$A$604,$H24,$F$2:$F$604,L$2),"") -> 0.52215794 | M24: =IFERROR(AVERAGEIFS($C$2:$C$604,$A$2:$A$604,$H24,$F$2:$F$604,M$2),"") -> 0.47911085 | N24: =IFERROR(AVERAGEIFS($C$2:$C$604,$A$2:$A$604,$H24,$F$2:$F$604,N$2),"") -> 0.49160777 | O24: =IFERROR(AVERAGEIFS($C$2:$C$604,$A$2:$A$604,$H24,$F$2:$F$604,O$2),"") -> 0.48312987 | P24: =IFERROR(AVERAGEIFS($C$2:$C$604,$A$2:$A$604,$H24,$F$2:$F$604,P$2),"") -> 0.47639723 | ... AJ24: =IFERROR(AVERAGEIFS($C$2:$C$604,$A$2:$A$604,$H24,$F$2:$F$604,AJ$2),"") -> 1.0320186
A25: BRA | B25: 1982 | C25: 0.45652572 | D25: 1975 | E25: 1988 | F25: =COUNTIFS($A$2:A25, A25) -> 8 | H25: MUS | I25: =IFERROR(AVERAGEIFS($C$2:$C$604,$A$2:$A$604,$H25,$F$2:$F$604,I$2),"") -> 0.55659383 | J25: =IFERROR(AVERAGEIFS($C$2:$C$604,$A$2:$A$604,$H25,$F$2:$F$604,J$2),"") -> 0.55687332 | K25: =IFERROR(AVERAGEIFS($C$2:$C$604,$A$2:$A$604,$H25,$F$2:$F$604,K$2),"") -> 0.55751063 | L25: =IFERROR(AVERAGEIFS($C$2:$C$604,$A$2:$A$604,$H25,$F$2:$F$604,L$2),"") -> 0.56097409 | M25: =IFERROR(AVERAGEIFS($C$2:$C$604,$A$2:$A$604,$H25,$F$2:$F$604,M$2),"") -> 0.56928999 | N25: =IFERROR(AVERAGEIFS($C$2:$C$604,$A$2:$A$604,$H25,$F$2:$F$604,N$2),"") -> 0.69705877 | O25: =IFERROR(AVERAGEIFS($C$2:$C$604,$A$2:$A$604,$H25,$F$2:$F$604,O$2),"") -> 0.69965795 | P25: =IFERROR(AVERAGEIFS($C$2:$C$604,$A$2:$A$604,$H25,$F$2:$F$604,P$2),"") -> 0.71930314 | ... X25: =IFERROR(AVERAGEIFS($C$2:$C$604,$A$2:$A$604,$H25,$F$2:$F$604,X$2),"") -> 1.0369949
A26: BRA | B26: 1983 | C26: 0.50476141 | D26: 1975 | E26: 1988 | F26: =COUNTIFS($A$2:A26, A26) -> 9 | H26: MYS | I26: =IFERROR(AVERAGEIFS($C$2:$C$604,$A$2:$A$604,$H26,$F$2:$F$604,I$2),"") -> 0.57761443 | J26: =IFERROR(AVERAGEIFS($C$2:$C$604,$A$2:$A$604,$H26,$F$2:$F$604,J$2),"") -> 0.62732928 | K26: =IFERROR(AVERAGEIFS($C$2:$C$604,$A$2:$A$604,$H26,$F$2:$F$604,K$2),"") -> 0.69926892 | L26: =IFERROR(AVERAGEIFS($C$2:$C$604,$A$2:$A$604,$H26,$F$2:$F$604,L$2),"") -> 0.74890132 | M26: =IFERROR(AVERAGEIFS($C$2:$C$604,$A$2:$A$604,$H26,$F$2:$F$604,M$2),"") -> 0.88174648 | N26: =IFERROR(AVERAGEIFS($C$2:$C$604,$A$2:$A$604,$H26,$F$2:$F$604,N$2),"") -> 1.0146604
A27: BRA | B27: 1984 | C27: 0.5039323 | D27: 1975 | E27: 1988 | F27: =COUNTIFS($A$2:A27, A27) -> 10 | H27: NPL | I27: =IFERROR(AVERAGEIFS($C$2:$C$604,$A$2:$A$604,$H27,$F$2:$F$604,I$2),"") -> 0.51652646 | J27: =IFERROR(AVERAGEIFS($C$2:$C$604,$A$2:$A$604,$H27,$F$2:$F$604,J$2),"") -> 0.59178455 | K27: =IFERROR(AVERAGEIFS($C$2:$C$604,$A$2:$A$604,$H27,$F$2:$F$604,K$2),"") -> 0.54589988 | L27: =IFERROR(AVERAGEIFS($C$2:$C$604,$A$2:$A$604,$H27,$F$2:$F$604,L$2),"") -> 0.46424653 | M27: =IFERROR(AVERAGEIFS($C$2:$C$604,$A$2:$A$604,$H27,$F$2:$F$604,M$2),"") -> 0.4875435 | N27: =IFERROR(AVERAGEIFS($C$2:$C$604,$A$2:$A$604,$H27,$F$2:$F$604,N$2),"") -> 0.50462271 | O27: =IFERROR(AVERAGEIFS($C$2:$C$604,$A$2:$A$604,$H27,$F$2:$F$604,O$2),"") -> 0.54467048 | P27: =IFERROR(AVERAGEIFS($C$2:$C$604,$A$2:$A$604,$H27,$F$2:$F$604,P$2),"") -> 0.56908274 | ... V27: =IFERROR(AVERAGEIFS($C$2:$C$604,$A$2:$A$604,$H27,$F$2:$F$604,V$2),"") -> 1.0365135
A28: BRA | B28: 1985 | C28: 0.44245833 | D28: 1975 | E28: 1988 | F28: =COUNTIFS($A$2:A28, A28) -> 11 | H28: OED | I28: =IFERROR(AVERAGEIFS($C$2:$C$604,$A$2:$A$604,$H28,$F$2:$F$604,I$2),"") -> 0.59576269 | J28: =IFERROR(AVERAGEIFS($C$2:$C$604,$A$2:$A$604,$H28,$F$2:$F$604,J$2),"") -> 0.62730371 | K28: =IFERROR(AVERAGEIFS($C$2:$C$604,$A$2:$A$604,$H28,$F$2:$F$604,K$2),"") -> 0.77800864 | L28: =IFERROR(AVERAGEIFS($C$2:$C$604,$A$2:$A$604,$H28,$F$2:$F$604,L$2),"") -> 0.81537962 | M28: =IFERROR(AVERAGEIFS($C$2:$C$604,$A$2:$A$604,$H28,$F$2:$F$604,M$2),"") -> 0.87101996 | N28: =IFERROR(AVERAGEIFS($C$2:$C$604,$A$2:$A$604,$H28,$F$2:$F$604,N$2),"") -> 0.89234077 | O28: =IFERROR(AVERAGEIFS($C$2:$C$604,$A$2:$A$604,$H28,$F$2:$F$604,O$2),"") -> 0.93421029 | P28: =IFERROR(AVERAGEIFS($C$2:$C$604,$A$2:$A$604,$H28,$F$2:$F$604,P$2),"") -> 0.95369281 | Q28: =IFERROR(AVERAGEIFS($C$2:$C$604,$A$2:$A$604,$H28,$F$2:$F$604,Q$2),"") -> 1.0087173
A29: BRA | B29: 1988 | C29: 1.0539101 | D29: 1975 | E29: 1988 | F29: =COUNTIFS($A$2:A29, A29) -> 12 | H29: PST | I29: =IFERROR(AVERAGEIFS($C$2:$C$604,$A$2:$A$604,$H29,$F$2:$F$604,I$2),"") -> 0.59997438 | J29: =IFERROR(AVERAGEIFS($C$2:$C$604,$A$2:$A$604,$H29,$F$2:$F$604,J$2),"") -> 0.6323052 | K29: =IFERROR(AVERAGEIFS($C$2:$C$604,$A$2:$A$604,$H29,$F$2:$F$604,K$2),"") -> 0.63948316 | L29: =IFERROR(AVERAGEIFS($C$2:$C$604,$A$2:$A$604,$H29,$F$2:$F$604,L$2),"") -> 0.78240109 | M29: =IFERROR(AVERAGEIFS($C$2:$C$604,$A$2:$A$604,$H29,$F$2:$F$604,M$2),"") -> 0.81981257 | N29: =IFERROR(AVERAGEIFS($C$2:$C$604,$A$2:$A$604,$H29,$F$2:$F$604,N$2),"") -> 0.87614426 | O29: =IFERROR(AVERAGEIFS($C$2:$C$604,$A$2:$A$604,$H29,$F$2:$F$604,O$2),"") -> 0.88095128 | P29: =IFERROR(AVERAGEIFS($C$2:$C$604,$A$2:$A$604,$H29,$F$2:$F$604,P$2),"") -> 0.86892037 | ... T29: =IFERROR(AVERAGEIFS($C$2:$C$604,$A$2:$A$604,$H29,$F$2:$F$604,T$2),"") -> 1.013589
A30: CAN | B30: 1978 | C30: 0.53032184 | D30: 1978 | E30: 2001 | F30: =COUNTIFS($A$2:A30, A30) -> 1 | H30: QAT | I30: =IFERROR(AVERAGEIFS($C$2:$C$604,$A$2:$A$604,$H30,$F$2:$F$604,I$2),"") -> 0.53255109 | J30: =IFERROR(AVERAGEIFS($C$2:$C$604,$A$2:$A$604,$H30,$F$2:$F$604,J$2),"") -> 0.65079763 | K30: =IFERROR(AVERAGEIFS($C$2:$C$604,$A$2:$A$604,$H30,$F$2:$F$604,K$2),"") -> 0.42060651 | L30: =IFERROR(AVERAGEIFS($C$2:$C$604,$A$2:$A$604,$H30,$F$2:$F$604,L$2),"") -> 0.35591401 | M30: =IFERROR(AVERAGEIFS($C$2:$C$604,$A$2:$A$604,$H30,$F$2:$F$604,M$2),"") -> 0.34696172 | N30: =IFERROR(AVERAGEIFS($C$2:$C$604,$A$2:$A$604,$H30,$F$2:$F$604,N$2),"") -> 0.31127184 | O30: =IFERROR(AVERAGEIFS($C$2:$C$604,$A$2:$A$604,$H30,$F$2:$F$604,O$2),"") -> 0.30550044 | P30: =IFERROR(AVERAGEIFS($C$2:$C$604,$A$2:$A$604,$H30,$F$2:$F$604,P$2),"") -> 0.38755958 | ... AK30: =IFERROR(AVERAGEIFS($C$2:$C$604,$A$2:$A$604,$H30,$F$2:$F$604,AK$2),"") -> 1.0063605
A31: CAN | B31: 1979 | C31: 0.55675991 | D31: 1978 | E31: 2001 | F31: =COUNTIFS($A$2:A31, A31) -> 2 | H31: SGP | I31: =IFERROR(AVERAGEIFS($C$2:$C$604,$A$2:$A$604,$H31,$F$2:$F$604,I$2),"") -> 0.50251135 | J31: =IFERROR(AVERAGEIFS($C$2:$C$604,$A$2:$A$604,$H31,$F$2:$F$604,J$2),"") -> 0.59082689 | K31: =IFERROR(AVERAGEIFS($C$2:$C$604,$A$2:$A$604,$H31,$F$2:$F$604,K$2),"") -> 0.53314525 | L31: =IFERROR(AVERAGEIFS($C$2:$C$604,$A$2:$A$604,$H31,$F$2:$F$604,L$2),"") -> 0.5600676 | M31: =IFERROR(AVERAGEIFS($C$2:$C$604,$A$2:$A$604,$H31,$F$2:$F$604,M$2),"") -> 0.57340336 | N31: =IFERROR(AVERAGEIFS($C$2:$C$604,$A$2:$A$604,$H31,$F$2:$F$604,N$2),"") -> 0.58172101 | O31: =IFERROR(AVERAGEIFS($C$2:$C$604,$A$2:$A$604,$H31,$F$2:$F$604,O$2),"") -> 0.60193921 | P31: =IFERROR(AVERAGEIFS($C$2:$C$604,$A$2:$A$604,$H31,$F$2:$F$604,P$2),"") -> 0.64589522 | ... AI31: =IFERROR(AVERAGEIFS($C$2:$C$604,$A$2:$A$604,$H31,$F$2:$F$604,AI$2),"") -> 1.0793107
A32: CAN | B32: 1980 | C32: 0.56416627 | D32: 1978 | E32: 2001 | F32: =COUNTIFS($A$2:A32, A32) -> 3 | H32: SWE | I32: =IFERROR(AVERAGEIFS($C$2:$C$604,$A$2:$A$604,$H32,$F$2:$F$604,I$2),"") -> 0.50268773 | J32: =IFERROR(AVERAGEIFS($C$2:$C$604,$A$2:$A$604,$H32,$F$2:$F$604,J$2),"") -> 0.51122588 | K32: =IFERROR(AVERAGEIFS($C$2:$C$604,$A$2:$A$604,$H32,$F$2:$F$604,K$2),"") -> 0.47427717 | L32: =IFERROR(AVERAGEIFS($C$2:$C$604,$A$2:$A$604,$H32,$F$2:$F$604,L$2),"") -> 0.47434823 | M32: =IFERROR(AVERAGEIFS($C$2:$C$604,$A$2:$A$604,$H32,$F$2:$F$604,M$2),"") -> 0.38149282 | N32: =IFERROR(AVERAGEIFS($C$2:$C$604,$A$2:$A$604,$H32,$F$2:$F$604,N$2),"") -> 0.34289051 | O32: =IFERROR(AVERAGEIFS($C$2:$C$604,$A$2:$A$604,$H32,$F$2:$F$604,O$2),"") -> 0.31324743 | P32: =IFERROR(AVERAGEIFS($C$2:$C$604,$A$2:$A$604,$H32,$F$2:$F$604,P$2),"") -> 0.31832135 | ... Z32: =IFERROR(AVERAGEIFS($C$2:$C$604,$A$2:$A$604,$H32,$F$2:$F$604,Z$2),"") -> 1.0272446
A33: CAN | B33: 1981 | C33: 0.69870344 | D33: 1978 | E33: 2001 | F33: =COUNTIFS($A$2:A33, A33) -> 4 | H33: TEA | I33: =IFERROR(AVERAGEIFS($C$2:$C$604,$A$2:$A$604,$H33,$F$2:$F$604,I$2),"") -> 0.51678539 | J33: =IFERROR(AVERAGEIFS($C$2:$C$604,$A$2:$A$604,$H33,$F$2:$F$604,J$2),"") -> 0.5279499 | K33: =IFERROR(AVERAGEIFS($C$2:$C$604,$A$2:$A$604,$H33,$F$2:$F$604,K$2),"") -> 0.54854408 | L33: =IFERROR(AVERAGEIFS($C$2:$C$604,$A$2:$A$604,$H33,$F$2:$F$604,L$2),"") -> 0.57594762 | M33: =IFERROR(AVERAGEIFS($C$2:$C$604,$A$2:$A$604,$H33,$F$2:$F$604,M$2),"") -> 0.63144843 | N33: =IFERROR(AVERAGEIFS($C$2:$C$604,$A$2:$A$604,$H33,$F$2:$F$604,N$2),"") -> 0.71586651 | O33: =IFERROR(AVERAGEIFS($C$2:$C$604,$A$2:$A$604,$H33,$F$2:$F$604,O$2),"") -> 0.68116983 | P33: =IFERROR(AVERAGEIFS($C$2:$C$604,$A$2:$A$604,$H33,$F$2:$F$604,P$2),"") -> 0.71317072 | ... Y33: =IFERROR(AVERAGEIFS($C$2:$C$604,$A$2:$A$604,$H33,$F$2:$F$604,Y$2),"") -> 1.0089026
A34: CAN | B34: 1982 | C34: 0.68063867 | D34: 1978 | E34: 2001 | F34: =COUNTIFS($A$2:A34, A34) -> 5 | H34: UMC | I34: =IFERROR(AVERAGEIFS($C$2:$C$604,$A$2:$A$604,$H34,$F$2:$F$604,I$2),"") -> 0.56202578 | J34: =IFERROR(AVERAGEIFS($C$2:$C$604,$A$2:$A$604,$H34,$F$2:$F$604,J$2),"") -> 0.55488991 | K34: =IFERROR(AVERAGEIFS($C$2:$C$604,$A$2:$A$604,$H34,$F$2:$F$604,K$2),"") -> 0.59843382 | L34: =IFERROR(AVERAGEIFS($C$2:$C$604,$A$2:$A$604,$H34,$F$2:$F$604,L$2),"") -> 0.59570335 | M34: =IFERROR(AVERAGEIFS($C$2:$C$604,$A$2:$A$604,$H34,$F$2:$F$604,M$2),"") -> 0.59487407 | N34: =IFERROR(AVERAGEIFS($C$2:$C$604,$A$2:$A$604,$H34,$F$2:$F$604,N$2),"") -> 0.65333611 | O34: =IFERROR(AVERAGEIFS($C$2:$C$604,$A$2:$A$604,$H34,$F$2:$F$604,O$2),"") -> 0.70889256 | P34: =IFERROR(AVERAGEIFS($C$2:$C$604,$A$2:$A$604,$H34,$F$2:$F$604,P$2),"") -> 0.68423853 | ... AA34: =IFERROR(AVERAGEIFS($C$2:$C$604,$A$2:$A$604,$H34,$F$2:$F$604,AA$2),"") -> 1.0960244
A35: CAN | B35: 1983 | C35: 0.63007339 | D35: 1978 | E35: 2001 | F35: =COUNTIFS($A$2:A35, A35) -> 6 | H35: VNM | I35: =IFERROR(AVERAGEIFS($C$2:$C$604,$A$2:$A$604,$H35,$F$2:$F$604,I$2),"") -> 0.58722431 | J35: =IFERROR(AVERAGEIFS($C$2:$C$604,$A$2:$A$604,$H35,$F$2:$F$604,J$2),"") -> 0.60466788 | K35: =IFERROR(AVERAGEIFS($C$2:$C$604,$A$2:$A$604,$H35,$F$2:$F$604,K$2),"") -> 0.65359542 | L35: =IFERROR(AVERAGEIFS($C$2:$C$604,$A$2:$A$604,$H35,$F$2:$F$604,L$2),"") -> 0.85639687 | M35: =IFERROR(AVERAGEIFS($C$2:$C$604,$A$2:$A$604,$H35,$F$2:$F$604,M$2),"") -> 0.82872771 | N35: =IFERROR(AVERAGEIFS($C$2:$C$604,$A$2:$A$604,$H35,$F$2:$F$604,N$2),"") -> 1.0332235
A36: CAN | B36: 1984 | C36: 0.62618781 | D36: 1978 | E36: 2001 | F36: =COUNTIFS($A$2:A36, A36) -> 7 | H36: ZAF | I36: =IFERROR(AVERAGEIFS($C$2:$C$604,$A$2:$A$604,$H36,$F$2:$F$604,I$2),"") -> 0.58716658 | J36: =IFERROR(AVERAGEIFS($C$2:$C$604,$A$2:$A$604,$H36,$F$2:$F$604,J$2),"") -> 0.57402719 | K36: =IFERROR(AVERAGEIFS($C$2:$C$604,$A$2:$A$604,$H36,$F$2:$F$604,K$2),"") -> 0.56836563 | L36: =IFERROR(AVERAGEIFS($C$2:$C$604,$A$2:$A$604,$H36,$F$2:$F$604,L$2),"") -> 0.54801341 | M36: =IFERROR(AVERAGEIFS($C$2:$C$604,$A$2:$A$604,$H36,$F$2:$F$604,M$2),"") -> 0.56189022 | N36: =IFERROR(AVERAGEIFS($C$2:$C$604,$A$2:$A$604,$H36,$F$2:$F$604,N$2),"") -> 0.57638229 | O36: =IFERROR(AVERAGEIFS($C$2:$C$604,$A$2:$A$604,$H36,$F$2:$F$604,O$2),"") -> 0.58124104 | P36: =IFERROR(AVERAGEIFS($C$2:$C$604,$A$2:$A$604,$H36,$F$2:$F$604,P$2),"") -> 0.57208691 | ... AK36: =IFERROR(AVERAGEIFS($C$2:$C$604,$A$2:$A$604,$H36,$F$2:$F$604,AK$2),"") -> 1.010586
A37: CAN | B37: 1985 | C37: 0.63228586 | D37: 1978 | E37: 2001 | F37: =COUNTIFS($A$2:A37, A37) -> 8
A38: CAN | B38: 1986 | C38: 0.63304787 | D38: 1978 | E38: 2001 | F38: =COUNTIFS($A$2:A38, A38) -> 9
A39: CAN | B39: 1987 | C39: 0.64086702 | D39: 1978 | E39: 2001 | F39: =COUNTIFS($A$2:A39, A39) -> 10
A40: CAN | B40: 1988 | C40: 0.66220286 | D40: 1978 | E40: 2001 | F40: =COUNTIFS($A$2:A40, A40) -> 11
...

Sheet Final
C4: Number of years | D4: Country | E4: 0 | F4: 1 | G4: 2 | H4: 3 | I4: 4 | J4: 5 | K4: 6 | L4: 7 | M4: 8 | N4: 9 | O4: 10 | P4: 11 | Q4: 12 | R4: 13 | S4: 14 | T4: 15 | U4: 16 | V4: 17 | W4: 18 | X4: 19 | Y4: 20 | Z4: 21 | AA4: 22 | AB4: 23 | AC4: 24 | AD4: 25 | AE4: 26 | AF4: 27 | AG4: 28 | AH4: 29 | AI4: 30 | AJ4: 31 | AK4: 32 | AL4: 33 | AM4: 34
A5: =VLOOKUP(B5,Setup!$B$3:$C$267,2,FALSE) -> Estonia | B5: EST | C5: =COUNT(E5:AM5) -> 5 | D5: Estonia | E5: 0.56573909 | F5: 0.76224565 | G5: 0.83747613 | H5: 0.89668873 | I5: 1.0138303
A6: =VLOOKUP(B6,Setup!$B$3:$C$267,2,FALSE) -> Cambodia | B6: KHM | C6: =COUNT(E6:AM6) -> 6 | D6: Cambodia | E6: 0.55489548 | F6: 0.61560889 | G6: 0.65462721 | H6: 0.73816427 | I6: 0.84323674 | J6: 1.0373277
A7: =VLOOKUP(B7,Setup!$B$3:$C$267,2,FALSE) -> Malaysia | B7: MYS | C7: =COUNT(E7:AM7) -> 6 | D7: Malaysia | E7: 0.57761443 | F7: 0.62732928 | G7: 0.69926892 | H7: 0.74890132 | I7: 0.88174648 | J7: 1.0146604
A8: =VLOOKUP(B8,Setup!$B$3:$C$267,2,FALSE) -> Viet Nam | B8: VNM | C8: =COUNT(E8:AM8) -> 6 | D8: Vietnam | E8: 0.58722431 | F8: 0.60466788 | G8: 0.65359542 | H8: 0.85639687 | I8: 0.82872771 | J8: 1.0332235
A9: =VLOOKUP(B9,Setup!$B$3:$C$267,2,FALSE) -> Iceland | B9: ISL | C9: =COUNT(E9:AM9) -> 6 | D9: Iceland | E9: 0.6378922 | F9: 0.6140587 | G9: 0.69988927 | H9: 0.9235795 | I9: 0.94088912 | J9: 0.99511217
A10: =VLOOKUP(B10,Setup!$B$3:$C$267,2,FALSE) -> Korea, Rep. | B10: KOR | C10: =COUNT(E10:AM10) -> 6 | D10: Korea | E10: 0.50146287 | F10: 0.54801785 | G10: 0.59608694 | H10: 0.64488126 | I10: 0.69186672 | J10: 0.99608241
A11: =VLOOKUP(B11,Setup!$B$3:$C$267,2,FALSE) -> OECD members | B11: OED | C11: =COUNT(E11:AM11) -> 9 | D11: OECD members | E11: 0.59576269 | F11: 0.62730371 | G11: 0.77800864 | H11: 0.81537962 | I11: 0.87101996 | J11: 0.89234077 | K11: 0.93421029 | L11: 0.95369281 | M11: 1.0087173
A12: =VLOOKUP(B12,Setup!$B$3:$C$267,2,FALSE) -> Greece | B12: GRC | C12: =COUNT(E12:AM12) -> 10 | D12: Greece | E12: 0.51696591 | F12: 0.54871833 | G12: 0.58731961 | H12: 0.63877543 | I12: 0.73657396 | J12: 0.77545437 | K12: 0.85798424 | L12: 0.90507314 | M12: 0.89224425 | N12: 1.1281428
A13: =VLOOKUP(B13,Setup!$B$3:$C$267,2,FALSE) -> Brazil | B13: BRA | C13: =COUNT(E13:AM13) -> 12 | D13: Brazil | E13: 0.52595594 | F13: 0.54468795 | G13: 0.54392781 | H13: 0.50425107 | I13: 0.51012911 | J13: 0.42053738 | K13: 0.44691434 | L13: 0.45652572 | M13: 0.50476141 | N13: 0.5039323 | O13: 0.44245833 | P13: 1.0539101
A14: =VLOOKUP(B14,Setup!$B$3:$C$267,2,FALSE) -> High income | B14: HIC | C14: =COUNT(E14:AM14) -> 12 | D14: High income | E14: 0.59566198 | F14: 0.62709509 | G14: 0.63352525 | H14: 0.77510484 | I14: 0.81130873 | J14: 0.8662968 | K14: 0.83777606 | L14: 0.87168824 | M14: 0.91741684 | N14: 0.9385691 | O14: 0.99525453 | P14: 1.0962072
A15: =VLOOKUP(B15,Setup!$B$3:$C$267,2,FALSE) -> Post-demographic dividend | B15: PST | C15: =COUNT(E15:AM15) -> 12 | D15: Post-demographic dividend | E15: 0.59997438 | F15: 0.6323052 | G15: 0.63948316 | H15: 0.78240109 | I15: 0.81981257 | J15: 0.87614426 | K15: 0.88095128 | L15: 0.86892037 | M15: 0.89744542 | N15: 0.93932749 | O15: 0.9578502 | P15: 1.013589
A16: =VLOOKUP(B16,Setup!$B$3:$C$267,2,FALSE) -> Nepal | B16: NPL | C16: =COUNT(E16:AM16) -> 14 | D16: Nepal | E16: 0.51652646 | F16: 0.59178455 | G16: 0.54589988 | H16: 0.46424653 | I16: 0.4875435 | J16: 0.50462271 | K16: 0.54467048 | L16: 0.56908274 | M16: 0.698408 | N16: 0.69189124 | O16: 0.76324608 | P16: 0.78945911 | Q16: 0.88440039 | R16: 1.0365135
A17: =VLOOKUP(B17,Setup!$B$3:$C$267,2,FALSE) -> Denmark | B17: DNK | C17: =COUNT(E17:AM17) -> 15 | D17: Denmark | E17: 0.54842236 | F17: 0.49720323 | G17: 0.47898527 | H17: 0.50797135 | I17: 0.50341353 | J17: 0.41882102 | K17: 0.39331498 | L17: 0.34261036 | M17: 0.30291792 | N17: 0.30371747 | O17: 0.31016248 | P17: 0.31566001 | Q17: 0.34342844 | R17: 0.34095559 | S17: 1.3206094
A18: =VLOOKUP(B18,Setup!$B$3:$C$267,2,FALSE) -> Australia | B18: AUS | C18: =COUNT(E18:AM18) -> 16 | D18: Australia | E18: 0.59177453 | F18: 0.60475371 | G18: 0.60033374 | H18: 0.61773309 | I18: 0.63192072 | J18: 0.66673424 | K18: 0.6966795 | L18: 0.71386377 | M18: 0.7520147 | N18: 0.78974896 | O18: 0.83904699 | P18: 0.87381033 | Q18: 0.88189283 | R18: 0.9106854 | S18: 0.9897007 | T18: 1.0244769
A19: =VLOOKUP(B19,Setup!$B$3:$C$267,2,FALSE) -> Mauritius | B19: MUS | C19: =COUNT(E19:AM19) -> 16 | D19: Mauritius | E19: 0.55659383 | F19: 0.55687332 | G19: 0.55751063 | H19: 0.56097409 | I19: 0.56928999 | J19: 0.69705877 | K19: 0.69965795 | L19: 0.71930314 | M19: 0.67639909 | N19: 0.70643396 | O19: 0.80688165 | P19: 0.78904357 | Q19: 0.84168399 | R19: 0.88087151 | S19: 0.97480597 | T19: 1.0369949
A20: =VLOOKUP(B20,Setup!$B$3:$C$267,2,FALSE) -> East Asia & Pacific (excluding high income) | B20: EAP | C20: =COUNT(E20:AM20) -> 17 | D20: East Asia & Pacific | E20: 0.51678539 | F20: 0.5279499 | G20: 0.54854408 | H20: 0.57594762 | I20: 0.63144843 | J20: 0.71586651 | K20: 0.68116983 | L20: 0.71317072 | M20: 0.76246487 | N20: 0.78085554 | O20: 0.79124761 | P20: 0.86967129 | Q20: 0.80738786 | R20: 0.80558229 | S20: 0.87240326 | T20: 0.9505452 | U20: 1.0089026
A21: =VLOOKUP(B21,Setup!$B$3:$C$267,2,FALSE) -> East Asia & Pacific (IDA & IBRD) | B21: TEA | C21: =COUNT(E21:AM21) -> 17 | D21: East Asia & Pacific | E21: 0.51678539 | F21: 0.5279499 | G21: 0.54854408 | H21: 0.57594762 | I21: 0.63144843 | J21: 0.71586651 | K21: 0.68116983 | L21: 0.71317072 | M21: 0.76246487 | N21: 0.78085554 | O21: 0.79124761 | P21: 0.86967129 | Q21: 0.80738786 | R21: 0.80558229 | S21: 0.87240326 | T21: 0.9505452 | U21: 1.0089026
A22: =VLOOKUP(B22,Setup!$B$3:$C$267,2,FALSE) -> Fiji | B22: FJI | C22: =COUNT(E22:AM22) -> 18 | D22: Fiji | E22: 0.55299121 | F22: 0.54742556 | G22: 0.61113472 | H22: 0.69191585 | I22: 0.79066689 | J22: 0.78749678 | K22: 0.85911351 | L22: 0.89605567 | M22: 0.8346155 | N22: 0.75388073 | O22: 0.76801256 | P22: 0.74888747 | Q22: 0.72596976 | R22: 0.78765929 | S22: 0.84425145 | T22: 0.86206681 | U22: 0.92796325 | V22: 1.0411388
A23: =VLOOKUP(B23,Setup!$B$3:$C$267,2,FALSE) -> Sweden | B23: SWE | C23: =COUNT(E23:AM23) -> 18 | D23: Sweden | E23: 0.50268773 | F23: 0.51122588 | G23: 0.47427717 | H23: 0.47434823 | I23: 0.38149282 | J23: 0.34289051 | K23: 0.31324743 | L23: 0.31832135 | M23: 0.34718775 | N23: 0.35832938 | O23: 0.37432187 | P23: 0.3979994 | Q23: 0.89547435 | R23: 0.89628767 | S23: 0.89911528 | T23: 0.91635026 | U23: 0.99270035 | V23: 1.0272446
A24: =VLOOKUP(B24,Setup!$B$3:$C$267,2,FALSE) -> IDA & IBRD total | B24: IBT | C24: =COUNT(E24:AM24) -> 18 | D24: IDA & IBRD total | E24: 0.50968485 | F24: 0.54209467 | G24: 0.53603608 | H24: 0.52463712 | I24: 0.54149668 | J24: 0.57366148 | K24: 0.57417863 | L24: 0.66697626 | M24: 0.68000376 | N24: 0.69018577 | O24: 0.73286024 | P24: 0.77760092 | Q24: 0.83052059 | R24: 0.91496573 | S24: 0.93118923 | T24: 0.92885775 | U24: 0.97765842 | V24: 0.99450323
A25: =VLOOKUP(B25,Setup!$B$3:$C$267,2,FALSE) -> Upper middle income | B25: UMC | C25: =COUNT(E25:AM25) -> 18 | D25: Upper middle income | E25: 0.56202578 | F25: 0.55488991 | G25: 0.59843382 | H25: 0.59570335 | I25: 0.59487407 | J25: 0.65333611 | K25: 0.70889256 | L25: 0.68423853 | M25: 0.66004284 | N25: 0.67361437 | O25: 0.69720803 | P25: 0.66822756 | Q25: 0.78947005 | R25: 0.80563039 | S25: 0.81570779 | T25: 0.87221146 | U25: 0.92936106 | V25: 0.98644677
A26: =VLOOKUP(B26,Setup!$B$3:$C$267,2,FALSE) -> Finland | B26: FIN | C26: =COUNT(E26:AM26) -> 20 | D26: Finland | E26: 0.52654566 | F26: 0.55436378 | G26: 0.60284483 | H26: 0.63732747 | I26: 0.69254734 | J26: 0.73413899 | K26: 0.76282884 | L26: 0.80105327 | M26: 0.86308636 | N26: 0.88133215 | O26: 0.89533784 | P26: 0.92075477 | Q26: 0.93313415 | R26: 0.93366204 | S26: 0.94985061 | T26: 0.9478437 | U26: 0.94031757 | V26: 0.94881525 | W26: 0.95919386 | X26: 1.0173825
A27: =VLOOKUP(B27,Setup!$B$3:$C$267,2,FALSE) -> IBRD only | B27: IBD | C27: =COUNT(E27:AM27) -> 20 | D27: IBRD only | E27: 0.52217992 | F27: 0.52643577 | G27: 0.50782132 | H27: 0.54539585 | I27: 0.58138825 | J27: 0.57333968 | K27: 0.55959342 | L27: 0.57808062 | M27: 0.60852693 | N27: 0.60543868 | O27: 0.70361725 | P27: 0.71630343 | Q27: 0.72731357 | R27: 0.77133526 | S27: 0.82278449 | T27: 0.87992445 | U27: 0.97029268 | V27: 0.98590103 | W27: 0.9815356 | X27: 1.0347022
A28: =VLOOKUP(B28,Setup!$B$3:$C$267,2,FALSE) -> Late-demographic dividend | B28: LTE | C28: =COUNT(E28:AM28) -> 21 | D28: Late-demographic dividend | E28: 0.52436949 | F28: 0.54615397 | G28: 0.56183174 | H28: 0.60548447 | I28: 0.6460444 | J28: 0.64574588 | K28: 0.72639419 | L28: 0.73410899 | M28: 0.69402692 | N28: 0.73736785 | O28: 0.77728472 | P28: 0.75408789 | Q28: 0.72080675 | R28: 0.72433588 | S28: 0.75202596 | T28: 0.75534092 | U28: 0.90795982 | V28: 0.906978 | W28: 0.89817709 | X28: 0.95244217 | Y28: 1.0037035
A29: =VLOOKUP(B29,Setup!$B$3:$C$267,2,FALSE) -> China | B29: CHN | C29: =COUNT(E29:AM29) -> 17 | D29: China | E29: 0.51093568 | F29: 0.50206253 | G29: 0.49659135 | H29: 0.5253389 | I29: 0.55912391 | J29: 0.56696263 | K29: 0.56876917 | L29: 0.60605562 | M29: 0.66069176 | N29: 0.75835001 | O29: 0.77899492 | P29: 0.7385706 | Q29: 0.76997676 | R29: 0.8603302 | S29: 0.88101074 | T29: 0.86053063 | U29: 0.96506392
A30: =VLOOKUP(B30,Setup!$B$3:$C$267,2,FALSE) -> Canada | B30: CAN | C30: =COUNT(E30:AM30) -> 24 | D30: Canada | E30: 0.53032184 | F30: 0.55675991 | G30: 0.56416627 | H30: 0.69870344 | I30: 0.68063867 | J30: 0.63007339 | K30: 0.62618781 | L30: 0.63228586 | M30: 0.63304787 | N30: 0.64086702 | O30: 0.66220286 | P30: 0.69800723 | Q30: 0.73068047 | R30: 0.74988921 | S30: 0.76528598 | T30: 0.75532002 | U30: 0.74751506 | V30: 0.73950514 | W30: 0.78633085 | X30: 0.81531269 | Y30: 0.7986254 | Z30: 0.77250111 | AA30: 0.73987738 | AB30: 1.2135283
A31: =VLOOKUP(B31,Setup!$B$3:$C$267,2,FALSE) -> Low & middle income | B31: LMY | C31: =COUNT(E31:AM31) -> 27 | D31: Low & middle income | E31: 0.61304163 | F31: 0.48584998 | G31: 0.50852522 | H31: 0.47029401 | I31: 0.48474739 | J31: 0.47719072 | K31: 0.47063182 | L31: 0.51566497 | M31: 0.51424306 | N31: 0.51596902 | O31: 0.55758839 | P31: 0.59484371 | Q31: 0.5845499 | R31: 0.57193398 | S31: 0.58616923 | T31: 0.61263609 | U31: 0.60384754 | V31: 0.7007155 | W31: 0.71713553 | X31: 0.7282527 | Y31: 0.77581752 | Z31: 0.81968052 | AA31: 0.8646038 | AB31: 0.94835061 | AC31: 0.96584289 | AD31: 0.96776707 | AE31: 1.023168
A32: =VLOOKUP(B32,Setup!$B$3:$C$267,2,FALSE) -> Singapore | B32: SGP | C32: =COUNT(E32:AM32) -> 27 | D32: Singapore | E32: 0.50251135 | F32: 0.59082689 | G32: 0.53314525 | H32: 0.5600676 | I32: 0.57340336 | J32: 0.58172101 | K32: 0.60193921 | L32: 0.64589522 | M32: 0.68907134 | N32: 0.75342646 | O32: 0.80120773 | P32: 0.85608808 | Q32: 0.85328681 | R32: 0.87605353 | S32: 0.84350018 | T32: 0.80576077 | U32: 0.76352693 | V32: 0.79540357 | W32: 0.79164675 | X32: 0.79871102 | Y32: 0.81085537 | Z32: 0.80971701 | AA32: 0.81190241 | AB32: 0.88293497 | AC32: 0.93741806 | AD32: 0.96470305 | AE32: 1.0793107
A33: =VLOOKUP(B33,Setup!$B$3:$C$267,2,FALSE) -> Lebanon | B33: LBN | C33: =COUNT(E33:AM33) -> 28 | D33: Lebanon | E33: 0.54550737 | F33: 0.65548294 | G33: 0.79377498 | H33: 0.45735857 | I33: 0.48948358 | J33: 0.42968592 | K33: 0.48816396 | L33: 0.54944633 | M33: 0.60548536 | N33: 0.6614 | O33: 0.73891315 | P33: 0.82267475 | Q33: 0.87901614 | R33: 0.86022851 | S33: 0.82574567 | T33: 0.7864287 | U33: 0.78125687 | V33: 0.69669526 | W33: 0.71811094 | X33: 0.7410642 | Y33: 0.76275273 | Z33: 0.72044694 | AA33: 0.8252848 | AB33: 0.89987857 | AC33: 0.8995533 | AD33: 0.93317293 | AE33: 0.98225548 | AF33: 1.0056612
A34: =VLOOKUP(B34,Setup!$B$3:$C$267,2,FALSE) -> Middle income | B34: MIC | C34: =COUNT(E34:AM34) -> 28 | D34: Middle income | E34: 0.51409687 | F34: 0.63239913 | G34: 0.50057896 | H34: 0.52215794 | I34: 0.47911085 | J34: 0.49160777 | K34: 0.48312987 | L34: 0.47639723 | M34: 0.52275603 | N34: 0.52331732 | O34: 0.52437274 | P34: 0.56775773 | Q34: 0.60565089 | R34: 0.59486949 | S34: 0.5821391 | T34: 0.59683556 | U34: 0.62338696 | V34: 0.61355648 | W34: 0.71087542 | X34: 0.72676914 | Y34: 0.73873603 | Z34: 0.78437293 | AA34: 0.82903342 | AB34: 0.87317408 | AC34: 0.9574646 | AD34: 0.97404489 | AE34: 0.97574843 | AF34: 1.0320186
A35: =VLOOKUP(B35,Setup!$B$3:$C$267,2,FALSE) -> Qatar | B35: QAT | C35: =COUNT(E35:AM35) -> 29 | D35: Qatar | E35: 0.53255109 | F35: 0.65079763 | G35: 0.42060651 | H35: 0.35591401 | I35: 0.34696172 | J35: 0.31127184 | K35: 0.30550044 | L35: 0.38755958 | M35: 0.34762918 | N35: 0.26848993 | O35: 0.34893285 | P35: 0.28678249 | Q35: 0.29988158 | R35: 0.28984867 | S35: 0.33721587 | T35: 0.35997458 | U35: 0.41576841 | V35: 0.40801185 | W35: 0.51735109 | X35: 0.45242405 | Y35: 0.39753025 | Z35: 0.3712844 | AA35: 0.40005319 | AB35: 0.4609678 | AC35: 0.70842533 | AD35: 0.79760609 | AE35: 0.80081674 | AF35: 0.80436747 | AG35: 1.0063605
A36: =VLOOKUP(B36,Setup!$B$3:$C$267,2,FALSE) -> South Africa | B36: ZAF | C36: =COUNT(E36:AM36) -> 29 | D36: South Africa | E36: 0.58716658 | F36: 0.57402719 | G36: 0.56836563 | H36: 0.54801341 | I36: 0.56189022 | J36: 0.57638229 | K36: 0.58124104 | L36: 0.57208691 | M36: 0.57943725 | N36: 0.55014934 | O36: 0.56690199 | P36: 0.54732694 | Q36: 0.53874822 | R36: 0.53406944 | S36: 0.52068011 | T36: 0.50085299 | U36: 0.53922118 | V36: 0.55294824 | W36: 0.58840093 | X36: 0.61759566 | Y36: 0.6519769 | Z36: 0.64857384 | AA36: 0.65225413 | AB36: 0.66753346 | AC36: 0.69140793 | AD36: 0.71938199 | AE36: 0.90983077 | AF36: 0.95828256 | AG36: 1.010586
A37: =VLOOKUP(B37,Setup!$B$3:$C$267,2,FALSE) -> Macao SAR, China | B37: MAC | C37: =COUNT(E37:AM37) -> 32 | D37: Macao SAR, China | E37: 0.52428203 | F37: 0.63188619 | G37: 0.61091472 | H37: 0.56016836 | I37: 0.59636472 | J37: 0.63597553 | K37: 0.62642857 | L37: 0.65594266 | M37: 0.66061666 | N37: 0.79743692 | O37: 0.79036804 | P37: 0.74266147 | Q37: 0.77819463 | R37: 0.84350684 | S37: 0.78936586 | T37: 0.80481806 | U37: 0.71969393 | V37: 0.63403789 | W37: 0.54579375 | X37: 0.48219402 | Y37: 0.40720756 | Z37: 0.4390169 | AA37: 0.40915157 | AB37: 0.47311519 | AC37: 0.53282047 | AD37: 0.57455805 | AE37: 0.56866027 | AF37: 0.56125322 | AG37: 0.57570932 | AH37: 0.62515085 | AI37: 0.77347359 | AJ37: 1.085117
A38: =VLOOKUP(B38,Setup!$B$3:$C$267,2,FALSE) -> Kuwait | B38: KWT | C38: =COUNT(E38:AM38) -> 35 | D38: Kuwait | E38: 0.52439232 | F38: 0.72187437 | G38: 0.71785041 | H38: 0.72431308 | I38: 0.7342704 | J38: 0.93545605 | K38: 0.83021432 | L38: 0.90845633 | M38: 0.73708156 | N38: 0.26730143 | O38: 0.17724191 | P38: 0.17162496 | Q38: 0.23078592 | R38: 0.30026251 | S38: 0.33652204 | T38: 0.46967969 | U38: 0.60729779 | V38: 0.54692084 | W38: 0.45389489 | X38: 0.56630542 | Y38: 0.58337066 | Z38: 0.59464569 | AA38: 0.56364544 | AB38: 0.50932667 | AC38: 0.49954142 | AD38: 0.59579388 | AE38: 0.57264928 | AF38: 0.79071927 | AG38: 0.74639383 | AH38: 0.60806258 | AI38: 0.55743368 | AJ38: 0.59751887 | AK38: 0.67640716 | AL38: 0.9851079 | AM38: 1.0518681

Sheet Sheet3
C2: EST | D2: 0.56573909 | E2: 0.76224565 | F2: 0.83747613 | G2: 0.89668873 | H2: 1.0138303
C3: KHM | D3: 0.55489548 | E3: 0.61560889 | F3: 0.65462721 | G3: 0.73816427 | H3: 0.84323674 | I3: 1.0373277
C4: MYS | D4: 0.57761443 | E4: 0.62732928 | F4: 0.69926892 | G4: 0.74890132 | H4: 0.88174648 | I4: 1.0146604
C5: VNM | D5: 0.58722431 | E5: 0.60466788 | F5: 0.65359542 | G5: 0.85639687 | H5: 0.82872771 | I5: 1.0332235
C6: ISL | D6: 0.6378922 | E6: 0.6140587 | F6: 0.69988927 | G6: 0.9235795 | H6: 0.94088912 | I6: 0.99511217
C7: KOR | D7: 0.50146287 | E7: 0.54801785 | F7: 0.59608694 | G7: 0.64488126 | H7: 0.69186672 | I7: 0.99608241
C8: LBN | D8: 0.54550737 | E8: 0.65548294 | F8: 0.79377498 | G8: 0.45735857 | H8: 0.48948358 | I8: 0.42968592 | J8: 0.48816396 | K8: 0.54944633 | L8: 0.60548536 | M8: 0.6614 | N8: 0.73891315 | O8: 0.82267475 | P8: 0.87901614 | Q8: 0.86022851 | R8: 0.82574567 | S8: 0.7864287 | T8: 0.78125687 | U8: 0.69669526 | V8: 0.71811094 | W8: 0.7410642 | X8: 0.76275273 | Y8: 0.72044694 | Z8: 0.8252848 | AA8: 0.89987857 | AB8: 0.8995533 | AC8: 0.93317293 | AD8: 0.98225548 | AE8: 1.0056612
C9: MIC | D9: 0.51409687 | E9: 0.63239913 | F9: 0.50057896 | G9: 0.52215794 | H9: 0.47911085 | I9: 0.49160777 | J9: 0.48312987 | K9: 0.47639723 | L9: 0.52275603 | M9: 0.52331732 | N9: 0.52437274 | O9: 0.56775773 | P9: 0.60565089 | Q9: 0.59486949 | R9: 0.5821391 | S9: 0.59683556 | T9: 0.62338696 | U9: 0.61355648 | V9: 0.71087542 | W9: 0.72676914 | X9: 0.73873603 | Y9: 0.78437293 | Z9: 0.82903342 | AA9: 0.87317408 | AB9: 0.9574646 | AC9: 0.97404489 | AD9: 0.97574843 | AE9: 1.0320186
C10: QAT | D10: 0.53255109 | E10: 0.65079763 | F10: 0.42060651 | G10: 0.35591401 | H10: 0.34696172 | I10: 0.31127184 | J10: 0.30550044 | K10: 0.38755958 | L10: 0.34762918 | M10: 0.26848993 | N10: 0.34893285 | O10: 0.28678249 | P10: 0.29988158 | Q10: 0.28984867 | R10: 0.33721587 | S10: 0.35997458 | T10: 0.41576841 | U10: 0.40801185 | V10: 0.51735109 | W10: 0.45242405 | X10: 0.39753025 | Y10: 0.3712844 | Z10: 0.40005319 | AA10: 0.4609678 | AB10: 0.70842533 | AC10: 0.79760609 | AD10: 0.80081674 | AE10: 0.80436747 | AF10: 1.0063605
C11: ZAF | D11: 0.58716658 | E11: 0.57402719 | F11: 0.56836563 | G11: 0.54801341 | H11: 0.56189022 | I11: 0.57638229 | J11: 0.58124104 | K11: 0.57208691 | L11: 0.57943725 | M11: 0.55014934 | N11: 0.56690199 | O11: 0.54732694 | P11: 0.53874822 | Q11: 0.53406944 | R11: 0.52068011 | S11: 0.50085299 | T11: 0.53922118 | U11: 0.55294824 | V11: 0.58840093 | W11: 0.61759566 | X11: 0.6519769 | Y11: 0.64857384 | Z11: 0.65225413 | AA11: 0.66753346 | AB11: 0.69140793 | AC11: 0.71938199 | AD11: 0.90983077 | AE11: 0.95828256 | AF11: 1.010586
C12: MAC | D12: 0.52428203 | E12: 0.63188619 | F12: 0.61091472 | G12: 0.56016836 | H12: 0.59636472 | I12: 0.63597553 | J12: 0.62642857 | K12: 0.65594266 | L12: 0.66061666 | M12: 0.79743692 | N12: 0.79036804 | O12: 0.74266147 | P12: 0.77819463 | Q12: 0.84350684 | R12: 0.78936586 | S12: 0.80481806 | T12: 0.71969393 | U12: 0.63403789 | V12: 0.54579375 | W12: 0.48219402 | X12: 0.40720756 | Y12: 0.4390169 | Z12: 0.40915157 | AA12: 0.47311519 | AB12: 0.53282047 | AC12: 0.57455805 | AD12: 0.56866027 | AE12: 0.56125322 | AF12: 0.57570932 | AG12: 0.62515085 | AH12: 0.77347359 | AI12: 1.085117
C13: KWT | D13: 0.52439232 | E13: 0.72187437 | F13: 0.71785041 | G13: 0.72431308 | H13: 0.7342704 | I13: 0.93545605 | J13: 0.83021432 | K13: 0.90845633 | L13: 0.73708156 | M13: 0.26730143 | N13: 0.17724191 | O13: 0.17162496 | P13: 0.23078592 | Q13: 0.30026251 | R13: 0.33652204 | S13: 0.46967969 | T13: 0.60729779 | U13: 0.54692084 | V13: 0.45389489 | W13: 0.56630542 | X13: 0.58337066 | Y13: 0.59464569 | Z13: 0.56364544 | AA13: 0.50932667 | AB13: 0.49954142 | AC13: 0.59579388 | AD13: 0.57264928 | AE13: 0.79071927 | AF13: 0.74639383 | AG13: 0.60806258 | AH13: 0.55743368 | AI13: 0.59751887 | AJ13: 0.67640716 | AK13: 0.9851079 | AL13: 1.0518681

Sheet Setup
B3: ABW | C3: Aruba
B4: AFE | C4: Africa Eastern and Southern
B5: AFG | C5: Afghanistan
B6: AFW | C6: Africa Western and Central
B7: AGO | C7: Angola
B8: ALB | C8: Albania
B9: AND | C9: Andorra
B10: ARB | C10: Arab World
B11: ARE | C11: United Arab Emirates
B12: ARG | C12: Argentina
B13: ARM | C13: Armenia
B14: ASM | C14: American Samoa
... B267: ZWE | C267: Zimbabwe
